
site.cd63130.tw1.ru [Fri Jan 17 18:59:49 2025] [error] [pid 1134770] src/server/wsgi_logger.c(147): [client 92.240.221.140:0] ERROR:root:Database connection error: unable to open database file
site.cd63130.tw1.ru [Fri Jan 17 18:59:49 2025] [error] [pid 1134770] src/server/wsgi_logger.c(147): [client 92.240.221.140:0] \xd0\x9e\xd1\x88\xd0\xb8\xd0\xb1\xd0\xba\xd0\xb0 \xd0\xbf\xd1\x80\xd0\xb8 \xd0\xb7\xd0\xb0\xd0\xbf\xd0\xb8\xd1\x81\xd0\xb8 \xd0\xbf\xd0\xbe\xd1\x81\xd0\xb5\xd1\x89\xd0\xb5\xd0\xbd\xd0\xb8\xd1\x8f: unable to open database file
site.cd63130.tw1.ru [Fri Jan 17 18:59:49 2025] [error] [pid 1134770] src/server/wsgi_logger.c(147): [client 92.240.221.140:0] INFO:site:Page visit: /admin/login - IP: gAAAAABnin512sMD2MwKQ9mjqmK1yi8TP2rrUdPW9TMTBGqonF50MMUk2mYY9iW_tLtBxiOVZQ5PAVADsGbMBUMIqoayYEvScg==
site.cd63130.tw1.ru [Fri Jan 17 19:03:10 2025] [error] [pid 1257514] src/server/wsgi_logger.c(147): [client 92.240.221.140:0] ERROR:root:Database connection error: unable to open database file
site.cd63130.tw1.ru [Fri Jan 17 19:03:10 2025] [error] [pid 1257514] src/server/wsgi_logger.c(147): [client 92.240.221.140:0] \xd0\x9e\xd1\x88\xd0\xb8\xd0\xb1\xd0\xba\xd0\xb0 \xd0\xbf\xd1\x80\xd0\xb8 \xd0\xb7\xd0\xb0\xd0\xbf\xd0\xb8\xd1\x81\xd0\xb8 \xd0\xbf\xd0\xbe\xd1\x81\xd0\xb5\xd1\x89\xd0\xb5\xd0\xbd\xd0\xb8\xd1\x8f: unable to open database file
site.cd63130.tw1.ru [Fri Jan 17 19:03:10 2025] [error] [pid 1257514] src/server/wsgi_logger.c(147): [client 92.240.221.140:0] INFO:site:Page visit: /admin/login - IP: gAAAAABnin8-51C4cTQpTW0v8nwxEzaHx93rZSjlNjXCCcAGy-qIWGfr5XHjdZUxl_PykoMmU2tLCcG8UhinuiVtbDzsDUeVIA==
site.cd63130.tw1.ru [Fri Jan 17 19:03:10 2025] [error] [pid 1257514] src/server/wsgi_logger.c(147): [client 92.240.221.140:0] ERROR:main:Exception on /admin/login [POST]
site.cd63130.tw1.ru [Fri Jan 17 19:03:10 2025] [error] [pid 1257514] src/server/wsgi_logger.c(147): [client 92.240.221.140:0] Traceback (most recent call last):
site.cd63130.tw1.ru [Fri Jan 17 19:03:10 2025] [error] [pid 1257514] src/server/wsgi_logger.c(147): [client 92.240.221.140:0]   File "/home/c/cd63130/.local/lib/python3.10/site-packages/flask/app.py", line 1455, in wsgi_app
site.cd63130.tw1.ru [Fri Jan 17 19:03:10 2025] [error] [pid 1257514] src/server/wsgi_logger.c(147): [client 92.240.221.140:0]     response = self.full_dispatch_request()
site.cd63130.tw1.ru [Fri Jan 17 19:03:10 2025] [error] [pid 1257514] src/server/wsgi_logger.c(147): [client 92.240.221.140:0]   File "/home/c/cd63130/.local/lib/python3.10/site-packages/flask/app.py", line 869, in full_dispatch_request
site.cd63130.tw1.ru [Fri Jan 17 19:03:10 2025] [error] [pid 1257514] src/server/wsgi_logger.c(147): [client 92.240.221.140:0]     rv = self.handle_user_exception(e)
site.cd63130.tw1.ru [Fri Jan 17 19:03:10 2025] [error] [pid 1257514] src/server/wsgi_logger.c(147): [client 92.240.221.140:0]   File "/home/c/cd63130/.local/lib/python3.10/site-packages/flask/app.py", line 865, in full_dispatch_request
site.cd63130.tw1.ru [Fri Jan 17 19:03:10 2025] [error] [pid 1257514] src/server/wsgi_logger.c(147): [client 92.240.221.140:0]     rv = self.preprocess_request()
site.cd63130.tw1.ru [Fri Jan 17 19:03:10 2025] [error] [pid 1257514] src/server/wsgi_logger.c(147): [client 92.240.221.140:0]   File "/home/c/cd63130/.local/lib/python3.10/site-packages/flask/app.py", line 1239, in preprocess_request
site.cd63130.tw1.ru [Fri Jan 17 19:03:10 2025] [error] [pid 1257514] src/server/wsgi_logger.c(147): [client 92.240.221.140:0]     rv = self.ensure_sync(before_func)()
site.cd63130.tw1.ru [Fri Jan 17 19:03:10 2025] [error] [pid 1257514] src/server/wsgi_logger.c(147): [client 92.240.221.140:0]   File "/home/c/cd63130/.local/lib/python3.10/site-packages/flask_wtf/csrf.py", line 229, in csrf_protect
site.cd63130.tw1.ru [Fri Jan 17 19:03:10 2025] [error] [pid 1257514] src/server/wsgi_logger.c(147): [client 92.240.221.140:0]     self.protect()
site.cd63130.tw1.ru [Fri Jan 17 19:03:10 2025] [error] [pid 1257514] src/server/wsgi_logger.c(147): [client 92.240.221.140:0]   File "/home/c/cd63130/.local/lib/python3.10/site-packages/flask_wtf/csrf.py", line 261, in protect
site.cd63130.tw1.ru [Fri Jan 17 19:03:10 2025] [error] [pid 1257514] src/server/wsgi_logger.c(147): [client 92.240.221.140:0]     validate_csrf(self._get_csrf_token())
site.cd63130.tw1.ru [Fri Jan 17 19:03:10 2025] [error] [pid 1257514] src/server/wsgi_logger.c(147): [client 92.240.221.140:0]   File "/home/c/cd63130/.local/lib/python3.10/site-packages/flask_wtf/csrf.py", line 85, in validate_csrf
site.cd63130.tw1.ru [Fri Jan 17 19:03:10 2025] [error] [pid 1257514] src/server/wsgi_logger.c(147): [client 92.240.221.140:0]     secret_key = _get_config(
site.cd63130.tw1.ru [Fri Jan 17 19:03:10 2025] [error] [pid 1257514] src/server/wsgi_logger.c(147): [client 92.240.221.140:0]   File "/home/c/cd63130/.local/lib/python3.10/site-packages/flask_wtf/csrf.py", line 136, in _get_config
site.cd63130.tw1.ru [Fri Jan 17 19:03:10 2025] [error] [pid 1257514] src/server/wsgi_logger.c(147): [client 92.240.221.140:0]     raise RuntimeError(message)
site.cd63130.tw1.ru [Fri Jan 17 19:03:10 2025] [error] [pid 1257514] src/server/wsgi_logger.c(147): [client 92.240.221.140:0] RuntimeError: A secret key is required to use CSRF.
site.cd63130.tw1.ru [Fri Jan 17 19:04:54 2025] [error] [pid 1306107] src/server/wsgi_logger.c(147): [client 92.240.221.140:0] ERROR:root:Database connection error: unable to open database file
site.cd63130.tw1.ru [Fri Jan 17 19:04:54 2025] [error] [pid 1306107] src/server/wsgi_logger.c(147): [client 92.240.221.140:0] \xd0\x9e\xd1\x88\xd0\xb8\xd0\xb1\xd0\xba\xd0\xb0 \xd0\xbf\xd1\x80\xd0\xb8 \xd0\xb7\xd0\xb0\xd0\xbf\xd0\xb8\xd1\x81\xd0\xb8 \xd0\xbf\xd0\xbe\xd1\x81\xd0\xb5\xd1\x89\xd0\xb5\xd0\xbd\xd0\xb8\xd1\x8f: unable to open database file
site.cd63130.tw1.ru [Fri Jan 17 19:04:55 2025] [error] [pid 1306107] src/server/wsgi_logger.c(147): [client 92.240.221.140:0] INFO:site:Page visit: /admin/login - IP: gAAAAABnin-n3GNMPsAmx9MNJQX6hSpDx-0--c42rzYyeU04cHXbG_eoGPHPo4RynT06I4wLxOnbBOyNYgKJ2NzirELfZtdG-Q==
site.cd63130.tw1.ru [Fri Jan 17 19:04:55 2025] [error] [pid 1306107] src/server/wsgi_logger.c(147): [client 92.240.221.140:0] ERROR:root:Login error: The current Flask app is not registered with this 'SQLAlchemy' instance. Did you forget to call 'init_app', or did you create multiple 'SQLAlchemy' instances?
site.cd63130.tw1.ru [Fri Jan 17 19:05:19 2025] [error] [pid 1333099] src/server/wsgi_logger.c(147): [client 92.240.221.140:0] ERROR:root:Database connection error: unable to open database file
site.cd63130.tw1.ru [Fri Jan 17 19:05:19 2025] [error] [pid 1333099] src/server/wsgi_logger.c(147): [client 92.240.221.140:0] \xd0\x9e\xd1\x88\xd0\xb8\xd0\xb1\xd0\xba\xd0\xb0 \xd0\xbf\xd1\x80\xd0\xb8 \xd0\xb7\xd0\xb0\xd0\xbf\xd0\xb8\xd1\x81\xd0\xb8 \xd0\xbf\xd0\xbe\xd1\x81\xd0\xb5\xd1\x89\xd0\xb5\xd0\xbd\xd0\xb8\xd1\x8f: unable to open database file
site.cd63130.tw1.ru [Fri Jan 17 19:05:19 2025] [error] [pid 1333099] src/server/wsgi_logger.c(147): [client 92.240.221.140:0] INFO:site:Page visit: /admin/login - IP: gAAAAABnin-_rUEajV06n_ZN1FnKec0ok54eZBrfBTZZg5b-_Z4yv57FRDVWKuv76nTtXP4gVnundB3ogak7rhXnNdb1ORB5sQ==
site.cd63130.tw1.ru [Fri Jan 17 19:05:19 2025] [error] [pid 1333099] src/server/wsgi_logger.c(147): [client 92.240.221.140:0] ERROR:root:Login error: The current Flask app is not registered with this 'SQLAlchemy' instance. Did you forget to call 'init_app', or did you create multiple 'SQLAlchemy' instances?
site.cd63130.tw1.ru [Fri Jan 17 19:15:22 2025] [error] [pid 1840312] src/server/mod_wsgi.c(3790): [client 45.90.63.97:0] mod_wsgi (pid=1840312): Failed to exec Python script file '/home/c/cd63130/site/public_html/passenger_wsgi.py'.
site.cd63130.tw1.ru [Fri Jan 17 19:15:22 2025] [error] [pid 1840312] src/server/wsgi_logger.c(628): [client 45.90.63.97:0] mod_wsgi (pid=1840312): Exception occurred processing WSGI script '/home/c/cd63130/site/public_html/passenger_wsgi.py'.
site.cd63130.tw1.ru [Fri Jan 17 19:15:22 2025] [error] [pid 1840312] src/server/wsgi_logger.c(147): [client 45.90.63.97:0] Traceback (most recent call last):
site.cd63130.tw1.ru [Fri Jan 17 19:15:22 2025] [error] [pid 1840312] src/server/wsgi_logger.c(147): [client 45.90.63.97:0]   File "/home/c/cd63130/site/public_html/passenger_wsgi.py", line 19, in <module>
site.cd63130.tw1.ru [Fri Jan 17 19:15:22 2025] [error] [pid 1840312] src/server/wsgi_logger.c(147): [client 45.90.63.97:0]     from main import app as application
site.cd63130.tw1.ru [Fri Jan 17 19:15:22 2025] [error] [pid 1840312] src/server/wsgi_logger.c(147): [client 45.90.63.97:0]   File "/home/c/cd63130/site/public_html/main.py", line 84, in <module>
site.cd63130.tw1.ru [Fri Jan 17 19:15:22 2025] [error] [pid 1840312] src/server/wsgi_logger.c(147): [client 45.90.63.97:0]     if not User.query.filter_by(username='admin').first():
site.cd63130.tw1.ru [Fri Jan 17 19:15:22 2025] [error] [pid 1840312] src/server/wsgi_logger.c(147): [client 45.90.63.97:0]   File "/home/c/cd63130/.local/lib/python3.10/site-packages/sqlalchemy/orm/query.py", line 2748, in first
site.cd63130.tw1.ru [Fri Jan 17 19:15:22 2025] [error] [pid 1840312] src/server/wsgi_logger.c(147): [client 45.90.63.97:0]     return self.limit(1)._iter().first()  # type: ignore
site.cd63130.tw1.ru [Fri Jan 17 19:15:22 2025] [error] [pid 1840312] src/server/wsgi_logger.c(147): [client 45.90.63.97:0]   File "/home/c/cd63130/.local/lib/python3.10/site-packages/sqlalchemy/orm/query.py", line 2847, in _iter
site.cd63130.tw1.ru [Fri Jan 17 19:15:22 2025] [error] [pid 1840312] src/server/wsgi_logger.c(147): [client 45.90.63.97:0]     result: Union[ScalarResult[_T], Result[_T]] = self.session.execute(
site.cd63130.tw1.ru [Fri Jan 17 19:15:22 2025] [error] [pid 1840312] src/server/wsgi_logger.c(147): [client 45.90.63.97:0]   File "/home/c/cd63130/.local/lib/python3.10/site-packages/sqlalchemy/orm/session.py", line 2308, in execute
site.cd63130.tw1.ru [Fri Jan 17 19:15:22 2025] [error] [pid 1840312] src/server/wsgi_logger.c(147): [client 45.90.63.97:0]     return self._execute_internal(
site.cd63130.tw1.ru [Fri Jan 17 19:15:22 2025] [error] [pid 1840312] src/server/wsgi_logger.c(147): [client 45.90.63.97:0]   File "/home/c/cd63130/.local/lib/python3.10/site-packages/sqlalchemy/orm/session.py", line 2178, in _execute_internal
site.cd63130.tw1.ru [Fri Jan 17 19:15:22 2025] [error] [pid 1840312] src/server/wsgi_logger.c(147): [client 45.90.63.97:0]     bind = self.get_bind(**bind_arguments)
site.cd63130.tw1.ru [Fri Jan 17 19:15:22 2025] [error] [pid 1840312] src/server/wsgi_logger.c(147): [client 45.90.63.97:0]   File "/home/c/cd63130/.local/lib/python3.10/site-packages/flask_sqlalchemy/session.py", line 53, in get_bind
site.cd63130.tw1.ru [Fri Jan 17 19:15:22 2025] [error] [pid 1840312] src/server/wsgi_logger.c(147): [client 45.90.63.97:0]     engines = self._db.engines
site.cd63130.tw1.ru [Fri Jan 17 19:15:22 2025] [error] [pid 1840312] src/server/wsgi_logger.c(147): [client 45.90.63.97:0]   File "/home/c/cd63130/.local/lib/python3.10/site-packages/flask_sqlalchemy/extension.py", line 690, in engines
site.cd63130.tw1.ru [Fri Jan 17 19:15:22 2025] [error] [pid 1840312] src/server/wsgi_logger.c(147): [client 45.90.63.97:0]     raise RuntimeError(
site.cd63130.tw1.ru [Fri Jan 17 19:15:22 2025] [error] [pid 1840312] src/server/wsgi_logger.c(147): [client 45.90.63.97:0] RuntimeError: The current Flask app is not registered with this 'SQLAlchemy' instance. Did you forget to call 'init_app', or did you create multiple 'SQLAlchemy' instances?
site.cd63130.tw1.ru [Fri Jan 17 19:15:22 2025] [error] [pid 1840983] src/server/mod_wsgi.c(3790): [client 45.90.63.97:0] mod_wsgi (pid=1840983): Failed to exec Python script file '/home/c/cd63130/site/public_html/passenger_wsgi.py'.
site.cd63130.tw1.ru [Fri Jan 17 19:15:22 2025] [error] [pid 1840983] src/server/wsgi_logger.c(628): [client 45.90.63.97:0] mod_wsgi (pid=1840983): Exception occurred processing WSGI script '/home/c/cd63130/site/public_html/passenger_wsgi.py'.
site.cd63130.tw1.ru [Fri Jan 17 19:15:22 2025] [error] [pid 1840983] src/server/wsgi_logger.c(147): [client 45.90.63.97:0] Traceback (most recent call last):
site.cd63130.tw1.ru [Fri Jan 17 19:15:22 2025] [error] [pid 1840983] src/server/wsgi_logger.c(147): [client 45.90.63.97:0]   File "/home/c/cd63130/site/public_html/passenger_wsgi.py", line 19, in <module>
site.cd63130.tw1.ru [Fri Jan 17 19:15:22 2025] [error] [pid 1840983] src/server/wsgi_logger.c(147): [client 45.90.63.97:0]     from main import app as application
site.cd63130.tw1.ru [Fri Jan 17 19:15:22 2025] [error] [pid 1840983] src/server/wsgi_logger.c(147): [client 45.90.63.97:0]   File "/home/c/cd63130/site/public_html/main.py", line 84, in <module>
site.cd63130.tw1.ru [Fri Jan 17 19:15:22 2025] [error] [pid 1840983] src/server/wsgi_logger.c(147): [client 45.90.63.97:0]     if not User.query.filter_by(username='admin').first():
site.cd63130.tw1.ru [Fri Jan 17 19:15:22 2025] [error] [pid 1840983] src/server/wsgi_logger.c(147): [client 45.90.63.97:0]   File "/home/c/cd63130/.local/lib/python3.10/site-packages/sqlalchemy/orm/query.py", line 2748, in first
site.cd63130.tw1.ru [Fri Jan 17 19:15:22 2025] [error] [pid 1840983] src/server/wsgi_logger.c(147): [client 45.90.63.97:0]     return self.limit(1)._iter().first()  # type: ignore
site.cd63130.tw1.ru [Fri Jan 17 19:15:22 2025] [error] [pid 1840983] src/server/wsgi_logger.c(147): [client 45.90.63.97:0]   File "/home/c/cd63130/.local/lib/python3.10/site-packages/sqlalchemy/orm/query.py", line 2847, in _iter
site.cd63130.tw1.ru [Fri Jan 17 19:15:22 2025] [error] [pid 1840983] src/server/wsgi_logger.c(147): [client 45.90.63.97:0]     result: Union[ScalarResult[_T], Result[_T]] = self.session.execute(
site.cd63130.tw1.ru [Fri Jan 17 19:15:22 2025] [error] [pid 1840983] src/server/wsgi_logger.c(147): [client 45.90.63.97:0]   File "/home/c/cd63130/.local/lib/python3.10/site-packages/sqlalchemy/orm/session.py", line 2308, in execute
site.cd63130.tw1.ru [Fri Jan 17 19:15:22 2025] [error] [pid 1840983] src/server/wsgi_logger.c(147): [client 45.90.63.97:0]     return self._execute_internal(
site.cd63130.tw1.ru [Fri Jan 17 19:15:22 2025] [error] [pid 1840983] src/server/wsgi_logger.c(147): [client 45.90.63.97:0]   File "/home/c/cd63130/.local/lib/python3.10/site-packages/sqlalchemy/orm/session.py", line 2178, in _execute_internal
site.cd63130.tw1.ru [Fri Jan 17 19:15:22 2025] [error] [pid 1840983] src/server/wsgi_logger.c(147): [client 45.90.63.97:0]     bind = self.get_bind(**bind_arguments)
site.cd63130.tw1.ru [Fri Jan 17 19:15:22 2025] [error] [pid 1840983] src/server/wsgi_logger.c(147): [client 45.90.63.97:0]   File "/home/c/cd63130/.local/lib/python3.10/site-packages/flask_sqlalchemy/session.py", line 53, in get_bind
site.cd63130.tw1.ru [Fri Jan 17 19:15:22 2025] [error] [pid 1840983] src/server/wsgi_logger.c(147): [client 45.90.63.97:0]     engines = self._db.engines
site.cd63130.tw1.ru [Fri Jan 17 19:15:22 2025] [error] [pid 1840983] src/server/wsgi_logger.c(147): [client 45.90.63.97:0]   File "/home/c/cd63130/.local/lib/python3.10/site-packages/flask_sqlalchemy/extension.py", line 690, in engines
site.cd63130.tw1.ru [Fri Jan 17 19:15:22 2025] [error] [pid 1840983] src/server/wsgi_logger.c(147): [client 45.90.63.97:0]     raise RuntimeError(
site.cd63130.tw1.ru [Fri Jan 17 19:15:22 2025] [error] [pid 1840983] src/server/wsgi_logger.c(147): [client 45.90.63.97:0] RuntimeError: The current Flask app is not registered with this 'SQLAlchemy' instance. Did you forget to call 'init_app', or did you create multiple 'SQLAlchemy' instances?
site.cd63130.tw1.ru [Fri Jan 17 19:15:23 2025] [error] [pid 1844334] src/server/mod_wsgi.c(3790): [client 45.90.63.97:0] mod_wsgi (pid=1844334): Failed to exec Python script file '/home/c/cd63130/site/public_html/passenger_wsgi.py'.
site.cd63130.tw1.ru [Fri Jan 17 19:15:23 2025] [error] [pid 1844334] src/server/wsgi_logger.c(628): [client 45.90.63.97:0] mod_wsgi (pid=1844334): Exception occurred processing WSGI script '/home/c/cd63130/site/public_html/passenger_wsgi.py'.
site.cd63130.tw1.ru [Fri Jan 17 19:15:23 2025] [error] [pid 1844334] src/server/wsgi_logger.c(147): [client 45.90.63.97:0] Traceback (most recent call last):
site.cd63130.tw1.ru [Fri Jan 17 19:15:23 2025] [error] [pid 1844334] src/server/wsgi_logger.c(147): [client 45.90.63.97:0]   File "/home/c/cd63130/site/public_html/passenger_wsgi.py", line 19, in <module>
site.cd63130.tw1.ru [Fri Jan 17 19:15:23 2025] [error] [pid 1844334] src/server/wsgi_logger.c(147): [client 45.90.63.97:0]     from main import app as application
site.cd63130.tw1.ru [Fri Jan 17 19:15:23 2025] [error] [pid 1844334] src/server/wsgi_logger.c(147): [client 45.90.63.97:0]   File "/home/c/cd63130/site/public_html/main.py", line 84, in <module>
site.cd63130.tw1.ru [Fri Jan 17 19:15:23 2025] [error] [pid 1844334] src/server/wsgi_logger.c(147): [client 45.90.63.97:0]     if not User.query.filter_by(username='admin').first():
site.cd63130.tw1.ru [Fri Jan 17 19:15:23 2025] [error] [pid 1844334] src/server/wsgi_logger.c(147): [client 45.90.63.97:0]   File "/home/c/cd63130/.local/lib/python3.10/site-packages/sqlalchemy/orm/query.py", line 2748, in first
site.cd63130.tw1.ru [Fri Jan 17 19:15:23 2025] [error] [pid 1844334] src/server/wsgi_logger.c(147): [client 45.90.63.97:0]     return self.limit(1)._iter().first()  # type: ignore
site.cd63130.tw1.ru [Fri Jan 17 19:15:23 2025] [error] [pid 1844334] src/server/wsgi_logger.c(147): [client 45.90.63.97:0]   File "/home/c/cd63130/.local/lib/python3.10/site-packages/sqlalchemy/orm/query.py", line 2847, in _iter
site.cd63130.tw1.ru [Fri Jan 17 19:15:23 2025] [error] [pid 1844334] src/server/wsgi_logger.c(147): [client 45.90.63.97:0]     result: Union[ScalarResult[_T], Result[_T]] = self.session.execute(
site.cd63130.tw1.ru [Fri Jan 17 19:15:23 2025] [error] [pid 1844334] src/server/wsgi_logger.c(147): [client 45.90.63.97:0]   File "/home/c/cd63130/.local/lib/python3.10/site-packages/sqlalchemy/orm/session.py", line 2308, in execute
site.cd63130.tw1.ru [Fri Jan 17 19:15:23 2025] [error] [pid 1844334] src/server/wsgi_logger.c(147): [client 45.90.63.97:0]     return self._execute_internal(
site.cd63130.tw1.ru [Fri Jan 17 19:15:23 2025] [error] [pid 1844334] src/server/wsgi_logger.c(147): [client 45.90.63.97:0]   File "/home/c/cd63130/.local/lib/python3.10/site-packages/sqlalchemy/orm/session.py", line 2178, in _execute_internal
site.cd63130.tw1.ru [Fri Jan 17 19:15:23 2025] [error] [pid 1844334] src/server/wsgi_logger.c(147): [client 45.90.63.97:0]     bind = self.get_bind(**bind_arguments)
site.cd63130.tw1.ru [Fri Jan 17 19:15:23 2025] [error] [pid 1844334] src/server/wsgi_logger.c(147): [client 45.90.63.97:0]   File "/home/c/cd63130/.local/lib/python3.10/site-packages/flask_sqlalchemy/session.py", line 53, in get_bind
site.cd63130.tw1.ru [Fri Jan 17 19:15:23 2025] [error] [pid 1844334] src/server/wsgi_logger.c(147): [client 45.90.63.97:0]     engines = self._db.engines
site.cd63130.tw1.ru [Fri Jan 17 19:15:23 2025] [error] [pid 1844334] src/server/wsgi_logger.c(147): [client 45.90.63.97:0]   File "/home/c/cd63130/.local/lib/python3.10/site-packages/flask_sqlalchemy/extension.py", line 690, in engines
site.cd63130.tw1.ru [Fri Jan 17 19:15:23 2025] [error] [pid 1844334] src/server/wsgi_logger.c(147): [client 45.90.63.97:0]     raise RuntimeError(
site.cd63130.tw1.ru [Fri Jan 17 19:15:23 2025] [error] [pid 1844334] src/server/wsgi_logger.c(147): [client 45.90.63.97:0] RuntimeError: The current Flask app is not registered with this 'SQLAlchemy' instance. Did you forget to call 'init_app', or did you create multiple 'SQLAlchemy' instances?
site.cd63130.tw1.ru [Fri Jan 17 19:15:24 2025] [error] [pid 1844896] src/server/mod_wsgi.c(3790): [client 45.90.63.97:0] mod_wsgi (pid=1844896): Failed to exec Python script file '/home/c/cd63130/site/public_html/passenger_wsgi.py'.
site.cd63130.tw1.ru [Fri Jan 17 19:15:24 2025] [error] [pid 1844896] src/server/wsgi_logger.c(628): [client 45.90.63.97:0] mod_wsgi (pid=1844896): Exception occurred processing WSGI script '/home/c/cd63130/site/public_html/passenger_wsgi.py'.
site.cd63130.tw1.ru [Fri Jan 17 19:15:24 2025] [error] [pid 1844896] src/server/wsgi_logger.c(147): [client 45.90.63.97:0] Traceback (most recent call last):
site.cd63130.tw1.ru [Fri Jan 17 19:15:24 2025] [error] [pid 1844896] src/server/wsgi_logger.c(147): [client 45.90.63.97:0]   File "/home/c/cd63130/site/public_html/passenger_wsgi.py", line 19, in <module>
site.cd63130.tw1.ru [Fri Jan 17 19:15:24 2025] [error] [pid 1844896] src/server/wsgi_logger.c(147): [client 45.90.63.97:0]     from main import app as application
site.cd63130.tw1.ru [Fri Jan 17 19:15:24 2025] [error] [pid 1844896] src/server/wsgi_logger.c(147): [client 45.90.63.97:0]   File "/home/c/cd63130/site/public_html/main.py", line 84, in <module>
site.cd63130.tw1.ru [Fri Jan 17 19:15:24 2025] [error] [pid 1844896] src/server/wsgi_logger.c(147): [client 45.90.63.97:0]     if not User.query.filter_by(username='admin').first():
site.cd63130.tw1.ru [Fri Jan 17 19:15:24 2025] [error] [pid 1844896] src/server/wsgi_logger.c(147): [client 45.90.63.97:0]   File "/home/c/cd63130/.local/lib/python3.10/site-packages/sqlalchemy/orm/query.py", line 2748, in first
site.cd63130.tw1.ru [Fri Jan 17 19:15:24 2025] [error] [pid 1844896] src/server/wsgi_logger.c(147): [client 45.90.63.97:0]     return self.limit(1)._iter().first()  # type: ignore
site.cd63130.tw1.ru [Fri Jan 17 19:15:24 2025] [error] [pid 1844896] src/server/wsgi_logger.c(147): [client 45.90.63.97:0]   File "/home/c/cd63130/.local/lib/python3.10/site-packages/sqlalchemy/orm/query.py", line 2847, in _iter
site.cd63130.tw1.ru [Fri Jan 17 19:15:24 2025] [error] [pid 1844896] src/server/wsgi_logger.c(147): [client 45.90.63.97:0]     result: Union[ScalarResult[_T], Result[_T]] = self.session.execute(
site.cd63130.tw1.ru [Fri Jan 17 19:15:24 2025] [error] [pid 1844896] src/server/wsgi_logger.c(147): [client 45.90.63.97:0]   File "/home/c/cd63130/.local/lib/python3.10/site-packages/sqlalchemy/orm/session.py", line 2308, in execute
site.cd63130.tw1.ru [Fri Jan 17 19:15:24 2025] [error] [pid 1844896] src/server/wsgi_logger.c(147): [client 45.90.63.97:0]     return self._execute_internal(
site.cd63130.tw1.ru [Fri Jan 17 19:15:24 2025] [error] [pid 1844896] src/server/wsgi_logger.c(147): [client 45.90.63.97:0]   File "/home/c/cd63130/.local/lib/python3.10/site-packages/sqlalchemy/orm/session.py", line 2178, in _execute_internal
site.cd63130.tw1.ru [Fri Jan 17 19:15:24 2025] [error] [pid 1844896] src/server/wsgi_logger.c(147): [client 45.90.63.97:0]     bind = self.get_bind(**bind_arguments)
site.cd63130.tw1.ru [Fri Jan 17 19:15:24 2025] [error] [pid 1844896] src/server/wsgi_logger.c(147): [client 45.90.63.97:0]   File "/home/c/cd63130/.local/lib/python3.10/site-packages/flask_sqlalchemy/session.py", line 53, in get_bind
site.cd63130.tw1.ru [Fri Jan 17 19:15:24 2025] [error] [pid 1844896] src/server/wsgi_logger.c(147): [client 45.90.63.97:0]     engines = self._db.engines
site.cd63130.tw1.ru [Fri Jan 17 19:15:24 2025] [error] [pid 1844896] src/server/wsgi_logger.c(147): [client 45.90.63.97:0]   File "/home/c/cd63130/.local/lib/python3.10/site-packages/flask_sqlalchemy/extension.py", line 690, in engines
site.cd63130.tw1.ru [Fri Jan 17 19:15:24 2025] [error] [pid 1844896] src/server/wsgi_logger.c(147): [client 45.90.63.97:0]     raise RuntimeError(
site.cd63130.tw1.ru [Fri Jan 17 19:15:24 2025] [error] [pid 1844896] src/server/wsgi_logger.c(147): [client 45.90.63.97:0] RuntimeError: The current Flask app is not registered with this 'SQLAlchemy' instance. Did you forget to call 'init_app', or did you create multiple 'SQLAlchemy' instances?
site.cd63130.tw1.ru [Fri Jan 17 19:15:26 2025] [error] [pid 1846122] src/server/mod_wsgi.c(3790): [client 45.90.63.116:0] mod_wsgi (pid=1846122): Failed to exec Python script file '/home/c/cd63130/site/public_html/passenger_wsgi.py'.
site.cd63130.tw1.ru [Fri Jan 17 19:15:26 2025] [error] [pid 1846122] src/server/wsgi_logger.c(628): [client 45.90.63.116:0] mod_wsgi (pid=1846122): Exception occurred processing WSGI script '/home/c/cd63130/site/public_html/passenger_wsgi.py'.
site.cd63130.tw1.ru [Fri Jan 17 19:15:26 2025] [error] [pid 1846122] src/server/wsgi_logger.c(147): [client 45.90.63.116:0] Traceback (most recent call last):
site.cd63130.tw1.ru [Fri Jan 17 19:15:26 2025] [error] [pid 1846122] src/server/wsgi_logger.c(147): [client 45.90.63.116:0]   File "/home/c/cd63130/site/public_html/passenger_wsgi.py", line 19, in <module>
site.cd63130.tw1.ru [Fri Jan 17 19:15:26 2025] [error] [pid 1846122] src/server/wsgi_logger.c(147): [client 45.90.63.116:0]     from main import app as application
site.cd63130.tw1.ru [Fri Jan 17 19:15:26 2025] [error] [pid 1846122] src/server/wsgi_logger.c(147): [client 45.90.63.116:0]   File "/home/c/cd63130/site/public_html/main.py", line 84, in <module>
site.cd63130.tw1.ru [Fri Jan 17 19:15:26 2025] [error] [pid 1846122] src/server/wsgi_logger.c(147): [client 45.90.63.116:0]     if not User.query.filter_by(username='admin').first():
site.cd63130.tw1.ru [Fri Jan 17 19:15:26 2025] [error] [pid 1846122] src/server/wsgi_logger.c(147): [client 45.90.63.116:0]   File "/home/c/cd63130/.local/lib/python3.10/site-packages/sqlalchemy/orm/query.py", line 2748, in first
site.cd63130.tw1.ru [Fri Jan 17 19:15:26 2025] [error] [pid 1846122] src/server/wsgi_logger.c(147): [client 45.90.63.116:0]     return self.limit(1)._iter().first()  # type: ignore
site.cd63130.tw1.ru [Fri Jan 17 19:15:26 2025] [error] [pid 1846122] src/server/wsgi_logger.c(147): [client 45.90.63.116:0]   File "/home/c/cd63130/.local/lib/python3.10/site-packages/sqlalchemy/orm/query.py", line 2847, in _iter
site.cd63130.tw1.ru [Fri Jan 17 19:15:26 2025] [error] [pid 1846122] src/server/wsgi_logger.c(147): [client 45.90.63.116:0]     result: Union[ScalarResult[_T], Result[_T]] = self.session.execute(
site.cd63130.tw1.ru [Fri Jan 17 19:15:26 2025] [error] [pid 1846122] src/server/wsgi_logger.c(147): [client 45.90.63.116:0]   File "/home/c/cd63130/.local/lib/python3.10/site-packages/sqlalchemy/orm/session.py", line 2308, in execute
site.cd63130.tw1.ru [Fri Jan 17 19:15:26 2025] [error] [pid 1846122] src/server/wsgi_logger.c(147): [client 45.90.63.116:0]     return self._execute_internal(
site.cd63130.tw1.ru [Fri Jan 17 19:15:26 2025] [error] [pid 1846122] src/server/wsgi_logger.c(147): [client 45.90.63.116:0]   File "/home/c/cd63130/.local/lib/python3.10/site-packages/sqlalchemy/orm/session.py", line 2178, in _execute_internal
site.cd63130.tw1.ru [Fri Jan 17 19:15:26 2025] [error] [pid 1846122] src/server/wsgi_logger.c(147): [client 45.90.63.116:0]     bind = self.get_bind(**bind_arguments)
site.cd63130.tw1.ru [Fri Jan 17 19:15:26 2025] [error] [pid 1846122] src/server/wsgi_logger.c(147): [client 45.90.63.116:0]   File "/home/c/cd63130/.local/lib/python3.10/site-packages/flask_sqlalchemy/session.py", line 53, in get_bind
site.cd63130.tw1.ru [Fri Jan 17 19:15:26 2025] [error] [pid 1846122] src/server/wsgi_logger.c(147): [client 45.90.63.116:0]     engines = self._db.engines
site.cd63130.tw1.ru [Fri Jan 17 19:15:26 2025] [error] [pid 1846122] src/server/wsgi_logger.c(147): [client 45.90.63.116:0]   File "/home/c/cd63130/.local/lib/python3.10/site-packages/flask_sqlalchemy/extension.py", line 690, in engines
site.cd63130.tw1.ru [Fri Jan 17 19:15:26 2025] [error] [pid 1846122] src/server/wsgi_logger.c(147): [client 45.90.63.116:0]     raise RuntimeError(
site.cd63130.tw1.ru [Fri Jan 17 19:15:26 2025] [error] [pid 1846122] src/server/wsgi_logger.c(147): [client 45.90.63.116:0] RuntimeError: The current Flask app is not registered with this 'SQLAlchemy' instance. Did you forget to call 'init_app', or did you create multiple 'SQLAlchemy' instances?
site.cd63130.tw1.ru [Fri Jan 17 19:15:27 2025] [error] [pid 1847042] src/server/mod_wsgi.c(3790): [client 176.53.218.82:0] mod_wsgi (pid=1847042): Failed to exec Python script file '/home/c/cd63130/site/public_html/passenger_wsgi.py'.
site.cd63130.tw1.ru [Fri Jan 17 19:15:27 2025] [error] [pid 1847042] src/server/wsgi_logger.c(628): [client 176.53.218.82:0] mod_wsgi (pid=1847042): Exception occurred processing WSGI script '/home/c/cd63130/site/public_html/passenger_wsgi.py'.
site.cd63130.tw1.ru [Fri Jan 17 19:15:27 2025] [error] [pid 1847042] src/server/wsgi_logger.c(147): [client 176.53.218.82:0] Traceback (most recent call last):
site.cd63130.tw1.ru [Fri Jan 17 19:15:27 2025] [error] [pid 1847042] src/server/wsgi_logger.c(147): [client 176.53.218.82:0]   File "/home/c/cd63130/site/public_html/passenger_wsgi.py", line 19, in <module>
site.cd63130.tw1.ru [Fri Jan 17 19:15:27 2025] [error] [pid 1847042] src/server/wsgi_logger.c(147): [client 176.53.218.82:0]     from main import app as application
site.cd63130.tw1.ru [Fri Jan 17 19:15:27 2025] [error] [pid 1847042] src/server/wsgi_logger.c(147): [client 176.53.218.82:0]   File "/home/c/cd63130/site/public_html/main.py", line 84, in <module>
site.cd63130.tw1.ru [Fri Jan 17 19:15:27 2025] [error] [pid 1847042] src/server/wsgi_logger.c(147): [client 176.53.218.82:0]     if not User.query.filter_by(username='admin').first():
site.cd63130.tw1.ru [Fri Jan 17 19:15:27 2025] [error] [pid 1847042] src/server/wsgi_logger.c(147): [client 176.53.218.82:0]   File "/home/c/cd63130/.local/lib/python3.10/site-packages/sqlalchemy/orm/query.py", line 2748, in first
site.cd63130.tw1.ru [Fri Jan 17 19:15:27 2025] [error] [pid 1847042] src/server/wsgi_logger.c(147): [client 176.53.218.82:0]     return self.limit(1)._iter().first()  # type: ignore
site.cd63130.tw1.ru [Fri Jan 17 19:15:27 2025] [error] [pid 1847042] src/server/wsgi_logger.c(147): [client 176.53.218.82:0]   File "/home/c/cd63130/.local/lib/python3.10/site-packages/sqlalchemy/orm/query.py", line 2847, in _iter
site.cd63130.tw1.ru [Fri Jan 17 19:15:27 2025] [error] [pid 1847042] src/server/wsgi_logger.c(147): [client 176.53.218.82:0]     result: Union[ScalarResult[_T], Result[_T]] = self.session.execute(
site.cd63130.tw1.ru [Fri Jan 17 19:15:27 2025] [error] [pid 1847042] src/server/wsgi_logger.c(147): [client 176.53.218.82:0]   File "/home/c/cd63130/.local/lib/python3.10/site-packages/sqlalchemy/orm/session.py", line 2308, in execute
site.cd63130.tw1.ru [Fri Jan 17 19:15:27 2025] [error] [pid 1847042] src/server/wsgi_logger.c(147): [client 176.53.218.82:0]     return self._execute_internal(
site.cd63130.tw1.ru [Fri Jan 17 19:15:27 2025] [error] [pid 1847042] src/server/wsgi_logger.c(147): [client 176.53.218.82:0]   File "/home/c/cd63130/.local/lib/python3.10/site-packages/sqlalchemy/orm/session.py", line 2178, in _execute_internal
site.cd63130.tw1.ru [Fri Jan 17 19:15:27 2025] [error] [pid 1847042] src/server/wsgi_logger.c(147): [client 176.53.218.82:0]     bind = self.get_bind(**bind_arguments)
site.cd63130.tw1.ru [Fri Jan 17 19:15:27 2025] [error] [pid 1847042] src/server/wsgi_logger.c(147): [client 176.53.218.82:0]   File "/home/c/cd63130/.local/lib/python3.10/site-packages/flask_sqlalchemy/session.py", line 53, in get_bind
site.cd63130.tw1.ru [Fri Jan 17 19:15:27 2025] [error] [pid 1847042] src/server/wsgi_logger.c(147): [client 176.53.218.82:0]     engines = self._db.engines
site.cd63130.tw1.ru [Fri Jan 17 19:15:27 2025] [error] [pid 1847042] src/server/wsgi_logger.c(147): [client 176.53.218.82:0]   File "/home/c/cd63130/.local/lib/python3.10/site-packages/flask_sqlalchemy/extension.py", line 690, in engines
site.cd63130.tw1.ru [Fri Jan 17 19:15:27 2025] [error] [pid 1847042] src/server/wsgi_logger.c(147): [client 176.53.218.82:0]     raise RuntimeError(
site.cd63130.tw1.ru [Fri Jan 17 19:15:27 2025] [error] [pid 1847042] src/server/wsgi_logger.c(147): [client 176.53.218.82:0] RuntimeError: The current Flask app is not registered with this 'SQLAlchemy' instance. Did you forget to call 'init_app', or did you create multiple 'SQLAlchemy' instances?
site.cd63130.tw1.ru [Fri Jan 17 19:15:28 2025] [error] [pid 1847845] src/server/mod_wsgi.c(3790): [client 176.53.222.105:0] mod_wsgi (pid=1847845): Failed to exec Python script file '/home/c/cd63130/site/public_html/passenger_wsgi.py'.
site.cd63130.tw1.ru [Fri Jan 17 19:15:28 2025] [error] [pid 1847845] src/server/wsgi_logger.c(628): [client 176.53.222.105:0] mod_wsgi (pid=1847845): Exception occurred processing WSGI script '/home/c/cd63130/site/public_html/passenger_wsgi.py'.
site.cd63130.tw1.ru [Fri Jan 17 19:15:28 2025] [error] [pid 1847845] src/server/wsgi_logger.c(147): [client 176.53.222.105:0] Traceback (most recent call last):
site.cd63130.tw1.ru [Fri Jan 17 19:15:28 2025] [error] [pid 1847845] src/server/wsgi_logger.c(147): [client 176.53.222.105:0]   File "/home/c/cd63130/site/public_html/passenger_wsgi.py", line 19, in <module>
site.cd63130.tw1.ru [Fri Jan 17 19:15:28 2025] [error] [pid 1847845] src/server/wsgi_logger.c(147): [client 176.53.222.105:0]     from main import app as application
site.cd63130.tw1.ru [Fri Jan 17 19:15:28 2025] [error] [pid 1847845] src/server/wsgi_logger.c(147): [client 176.53.222.105:0]   File "/home/c/cd63130/site/public_html/main.py", line 84, in <module>
site.cd63130.tw1.ru [Fri Jan 17 19:15:28 2025] [error] [pid 1847845] src/server/wsgi_logger.c(147): [client 176.53.222.105:0]     if not User.query.filter_by(username='admin').first():
site.cd63130.tw1.ru [Fri Jan 17 19:15:28 2025] [error] [pid 1847845] src/server/wsgi_logger.c(147): [client 176.53.222.105:0]   File "/home/c/cd63130/.local/lib/python3.10/site-packages/sqlalchemy/orm/query.py", line 2748, in first
site.cd63130.tw1.ru [Fri Jan 17 19:15:28 2025] [error] [pid 1847845] src/server/wsgi_logger.c(147): [client 176.53.222.105:0]     return self.limit(1)._iter().first()  # type: ignore
site.cd63130.tw1.ru [Fri Jan 17 19:15:28 2025] [error] [pid 1847845] src/server/wsgi_logger.c(147): [client 176.53.222.105:0]   File "/home/c/cd63130/.local/lib/python3.10/site-packages/sqlalchemy/orm/query.py", line 2847, in _iter
site.cd63130.tw1.ru [Fri Jan 17 19:15:28 2025] [error] [pid 1847845] src/server/wsgi_logger.c(147): [client 176.53.222.105:0]     result: Union[ScalarResult[_T], Result[_T]] = self.session.execute(
site.cd63130.tw1.ru [Fri Jan 17 19:15:28 2025] [error] [pid 1847845] src/server/wsgi_logger.c(147): [client 176.53.222.105:0]   File "/home/c/cd63130/.local/lib/python3.10/site-packages/sqlalchemy/orm/session.py", line 2308, in execute
site.cd63130.tw1.ru [Fri Jan 17 19:15:28 2025] [error] [pid 1847845] src/server/wsgi_logger.c(147): [client 176.53.222.105:0]     return self._execute_internal(
site.cd63130.tw1.ru [Fri Jan 17 19:15:28 2025] [error] [pid 1847845] src/server/wsgi_logger.c(147): [client 176.53.222.105:0]   File "/home/c/cd63130/.local/lib/python3.10/site-packages/sqlalchemy/orm/session.py", line 2178, in _execute_internal
site.cd63130.tw1.ru [Fri Jan 17 19:15:28 2025] [error] [pid 1847845] src/server/wsgi_logger.c(147): [client 176.53.222.105:0]     bind = self.get_bind(**bind_arguments)
site.cd63130.tw1.ru [Fri Jan 17 19:15:28 2025] [error] [pid 1847845] src/server/wsgi_logger.c(147): [client 176.53.222.105:0]   File "/home/c/cd63130/.local/lib/python3.10/site-packages/flask_sqlalchemy/session.py", line 53, in get_bind
site.cd63130.tw1.ru [Fri Jan 17 19:15:28 2025] [error] [pid 1847845] src/server/wsgi_logger.c(147): [client 176.53.222.105:0]     engines = self._db.engines
site.cd63130.tw1.ru [Fri Jan 17 19:15:28 2025] [error] [pid 1847845] src/server/wsgi_logger.c(147): [client 176.53.222.105:0]   File "/home/c/cd63130/.local/lib/python3.10/site-packages/flask_sqlalchemy/extension.py", line 690, in engines
site.cd63130.tw1.ru [Fri Jan 17 19:15:28 2025] [error] [pid 1847845] src/server/wsgi_logger.c(147): [client 176.53.222.105:0]     raise RuntimeError(
site.cd63130.tw1.ru [Fri Jan 17 19:15:28 2025] [error] [pid 1847845] src/server/wsgi_logger.c(147): [client 176.53.222.105:0] RuntimeError: The current Flask app is not registered with this 'SQLAlchemy' instance. Did you forget to call 'init_app', or did you create multiple 'SQLAlchemy' instances?
site.cd63130.tw1.ru [Fri Jan 17 19:15:29 2025] [error] [pid 1855661] src/server/mod_wsgi.c(3790): [client 45.90.63.11:0] mod_wsgi (pid=1855661): Failed to exec Python script file '/home/c/cd63130/site/public_html/passenger_wsgi.py'.
site.cd63130.tw1.ru [Fri Jan 17 19:15:29 2025] [error] [pid 1855661] src/server/wsgi_logger.c(628): [client 45.90.63.11:0] mod_wsgi (pid=1855661): Exception occurred processing WSGI script '/home/c/cd63130/site/public_html/passenger_wsgi.py'.
site.cd63130.tw1.ru [Fri Jan 17 19:15:29 2025] [error] [pid 1855661] src/server/wsgi_logger.c(147): [client 45.90.63.11:0] Traceback (most recent call last):
site.cd63130.tw1.ru [Fri Jan 17 19:15:29 2025] [error] [pid 1855661] src/server/wsgi_logger.c(147): [client 45.90.63.11:0]   File "/home/c/cd63130/site/public_html/passenger_wsgi.py", line 19, in <module>
site.cd63130.tw1.ru [Fri Jan 17 19:15:29 2025] [error] [pid 1855661] src/server/wsgi_logger.c(147): [client 45.90.63.11:0]     from main import app as application
site.cd63130.tw1.ru [Fri Jan 17 19:15:29 2025] [error] [pid 1855661] src/server/wsgi_logger.c(147): [client 45.90.63.11:0]   File "/home/c/cd63130/site/public_html/main.py", line 84, in <module>
site.cd63130.tw1.ru [Fri Jan 17 19:15:29 2025] [error] [pid 1855661] src/server/wsgi_logger.c(147): [client 45.90.63.11:0]     if not User.query.filter_by(username='admin').first():
site.cd63130.tw1.ru [Fri Jan 17 19:15:29 2025] [error] [pid 1855661] src/server/wsgi_logger.c(147): [client 45.90.63.11:0]   File "/home/c/cd63130/.local/lib/python3.10/site-packages/sqlalchemy/orm/query.py", line 2748, in first
site.cd63130.tw1.ru [Fri Jan 17 19:15:29 2025] [error] [pid 1855661] src/server/wsgi_logger.c(147): [client 45.90.63.11:0]     return self.limit(1)._iter().first()  # type: ignore
site.cd63130.tw1.ru [Fri Jan 17 19:15:29 2025] [error] [pid 1855661] src/server/wsgi_logger.c(147): [client 45.90.63.11:0]   File "/home/c/cd63130/.local/lib/python3.10/site-packages/sqlalchemy/orm/query.py", line 2847, in _iter
site.cd63130.tw1.ru [Fri Jan 17 19:15:29 2025] [error] [pid 1855661] src/server/wsgi_logger.c(147): [client 45.90.63.11:0]     result: Union[ScalarResult[_T], Result[_T]] = self.session.execute(
site.cd63130.tw1.ru [Fri Jan 17 19:15:29 2025] [error] [pid 1855661] src/server/wsgi_logger.c(147): [client 45.90.63.11:0]   File "/home/c/cd63130/.local/lib/python3.10/site-packages/sqlalchemy/orm/session.py", line 2308, in execute
site.cd63130.tw1.ru [Fri Jan 17 19:15:29 2025] [error] [pid 1855661] src/server/wsgi_logger.c(147): [client 45.90.63.11:0]     return self._execute_internal(
site.cd63130.tw1.ru [Fri Jan 17 19:15:29 2025] [error] [pid 1855661] src/server/wsgi_logger.c(147): [client 45.90.63.11:0]   File "/home/c/cd63130/.local/lib/python3.10/site-packages/sqlalchemy/orm/session.py", line 2178, in _execute_internal
site.cd63130.tw1.ru [Fri Jan 17 19:15:29 2025] [error] [pid 1855661] src/server/wsgi_logger.c(147): [client 45.90.63.11:0]     bind = self.get_bind(**bind_arguments)
site.cd63130.tw1.ru [Fri Jan 17 19:15:29 2025] [error] [pid 1855661] src/server/wsgi_logger.c(147): [client 45.90.63.11:0]   File "/home/c/cd63130/.local/lib/python3.10/site-packages/flask_sqlalchemy/session.py", line 53, in get_bind
site.cd63130.tw1.ru [Fri Jan 17 19:15:29 2025] [error] [pid 1855661] src/server/wsgi_logger.c(147): [client 45.90.63.11:0]     engines = self._db.engines
site.cd63130.tw1.ru [Fri Jan 17 19:15:29 2025] [error] [pid 1855661] src/server/wsgi_logger.c(147): [client 45.90.63.11:0]   File "/home/c/cd63130/.local/lib/python3.10/site-packages/flask_sqlalchemy/extension.py", line 690, in engines
site.cd63130.tw1.ru [Fri Jan 17 19:15:29 2025] [error] [pid 1855661] src/server/wsgi_logger.c(147): [client 45.90.63.11:0]     raise RuntimeError(
site.cd63130.tw1.ru [Fri Jan 17 19:15:29 2025] [error] [pid 1855661] src/server/wsgi_logger.c(147): [client 45.90.63.11:0] RuntimeError: The current Flask app is not registered with this 'SQLAlchemy' instance. Did you forget to call 'init_app', or did you create multiple 'SQLAlchemy' instances?
site.cd63130.tw1.ru [Fri Jan 17 19:35:00 2025] [error] [pid 2544577] src/server/mod_wsgi.c(3790): [client 92.240.221.140:0] mod_wsgi (pid=2544577): Failed to exec Python script file '/home/c/cd63130/site/public_html/passenger_wsgi.py'.
site.cd63130.tw1.ru [Fri Jan 17 19:35:00 2025] [error] [pid 2544577] src/server/wsgi_logger.c(628): [client 92.240.221.140:0] mod_wsgi (pid=2544577): Exception occurred processing WSGI script '/home/c/cd63130/site/public_html/passenger_wsgi.py'.
site.cd63130.tw1.ru [Fri Jan 17 19:35:00 2025] [error] [pid 2544577] src/server/wsgi_logger.c(147): [client 92.240.221.140:0] Traceback (most recent call last):
site.cd63130.tw1.ru [Fri Jan 17 19:35:00 2025] [error] [pid 2544577] src/server/wsgi_logger.c(147): [client 92.240.221.140:0]   File "/home/c/cd63130/site/public_html/passenger_wsgi.py", line 19, in <module>
site.cd63130.tw1.ru [Fri Jan 17 19:35:00 2025] [error] [pid 2544577] src/server/wsgi_logger.c(147): [client 92.240.221.140:0]     from main import app as application
site.cd63130.tw1.ru [Fri Jan 17 19:35:00 2025] [error] [pid 2544577] src/server/wsgi_logger.c(147): [client 92.240.221.140:0]   File "/home/c/cd63130/site/public_html/main.py", line 86, in <module>
site.cd63130.tw1.ru [Fri Jan 17 19:35:00 2025] [error] [pid 2544577] src/server/wsgi_logger.c(147): [client 92.240.221.140:0]     user.set_password('admin')
site.cd63130.tw1.ru [Fri Jan 17 19:35:00 2025] [error] [pid 2544577] src/server/wsgi_logger.c(147): [client 92.240.221.140:0] AttributeError: 'User' object has no attribute 'set_password'
site.cd63130.tw1.ru [Fri Jan 17 19:35:02 2025] [error] [pid 2544947] src/server/mod_wsgi.c(3790): [client 92.240.221.140:0] mod_wsgi (pid=2544947): Failed to exec Python script file '/home/c/cd63130/site/public_html/passenger_wsgi.py'.
site.cd63130.tw1.ru [Fri Jan 17 19:35:02 2025] [error] [pid 2544947] src/server/wsgi_logger.c(628): [client 92.240.221.140:0] mod_wsgi (pid=2544947): Exception occurred processing WSGI script '/home/c/cd63130/site/public_html/passenger_wsgi.py'.
site.cd63130.tw1.ru [Fri Jan 17 19:35:02 2025] [error] [pid 2544947] src/server/wsgi_logger.c(147): [client 92.240.221.140:0] Traceback (most recent call last):
site.cd63130.tw1.ru [Fri Jan 17 19:35:02 2025] [error] [pid 2544947] src/server/wsgi_logger.c(147): [client 92.240.221.140:0]   File "/home/c/cd63130/site/public_html/passenger_wsgi.py", line 19, in <module>
site.cd63130.tw1.ru [Fri Jan 17 19:35:02 2025] [error] [pid 2544947] src/server/wsgi_logger.c(147): [client 92.240.221.140:0]     from main import app as application
site.cd63130.tw1.ru [Fri Jan 17 19:35:02 2025] [error] [pid 2544947] src/server/wsgi_logger.c(147): [client 92.240.221.140:0]   File "/home/c/cd63130/site/public_html/main.py", line 86, in <module>
site.cd63130.tw1.ru [Fri Jan 17 19:35:02 2025] [error] [pid 2544947] src/server/wsgi_logger.c(147): [client 92.240.221.140:0]     user.set_password('admin')
site.cd63130.tw1.ru [Fri Jan 17 19:35:02 2025] [error] [pid 2544947] src/server/wsgi_logger.c(147): [client 92.240.221.140:0] AttributeError: 'User' object has no attribute 'set_password'
site.cd63130.tw1.ru [Fri Jan 17 19:35:04 2025] [error] [pid 2550355] src/server/mod_wsgi.c(3790): [client 92.240.221.140:0] mod_wsgi (pid=2550355): Failed to exec Python script file '/home/c/cd63130/site/public_html/passenger_wsgi.py'.
site.cd63130.tw1.ru [Fri Jan 17 19:35:04 2025] [error] [pid 2550355] src/server/wsgi_logger.c(628): [client 92.240.221.140:0] mod_wsgi (pid=2550355): Exception occurred processing WSGI script '/home/c/cd63130/site/public_html/passenger_wsgi.py'.
site.cd63130.tw1.ru [Fri Jan 17 19:35:04 2025] [error] [pid 2550355] src/server/wsgi_logger.c(147): [client 92.240.221.140:0] Traceback (most recent call last):
site.cd63130.tw1.ru [Fri Jan 17 19:35:04 2025] [error] [pid 2550355] src/server/wsgi_logger.c(147): [client 92.240.221.140:0]   File "/home/c/cd63130/site/public_html/passenger_wsgi.py", line 19, in <module>
site.cd63130.tw1.ru [Fri Jan 17 19:35:04 2025] [error] [pid 2550355] src/server/wsgi_logger.c(147): [client 92.240.221.140:0]     from main import app as application
site.cd63130.tw1.ru [Fri Jan 17 19:35:04 2025] [error] [pid 2550355] src/server/wsgi_logger.c(147): [client 92.240.221.140:0]   File "/home/c/cd63130/site/public_html/main.py", line 86, in <module>
site.cd63130.tw1.ru [Fri Jan 17 19:35:04 2025] [error] [pid 2550355] src/server/wsgi_logger.c(147): [client 92.240.221.140:0]     user.set_password('admin')
site.cd63130.tw1.ru [Fri Jan 17 19:35:04 2025] [error] [pid 2550355] src/server/wsgi_logger.c(147): [client 92.240.221.140:0] AttributeError: 'User' object has no attribute 'set_password'
site.cd63130.tw1.ru [Fri Jan 17 19:35:04 2025] [error] [pid 2551433] src/server/mod_wsgi.c(3790): [client 92.240.221.140:0] mod_wsgi (pid=2551433): Failed to exec Python script file '/home/c/cd63130/site/public_html/passenger_wsgi.py'.
site.cd63130.tw1.ru [Fri Jan 17 19:35:04 2025] [error] [pid 2551433] src/server/wsgi_logger.c(628): [client 92.240.221.140:0] mod_wsgi (pid=2551433): Exception occurred processing WSGI script '/home/c/cd63130/site/public_html/passenger_wsgi.py'.
site.cd63130.tw1.ru [Fri Jan 17 19:35:04 2025] [error] [pid 2551433] src/server/wsgi_logger.c(147): [client 92.240.221.140:0] Traceback (most recent call last):
site.cd63130.tw1.ru [Fri Jan 17 19:35:04 2025] [error] [pid 2551433] src/server/wsgi_logger.c(147): [client 92.240.221.140:0]   File "/home/c/cd63130/site/public_html/passenger_wsgi.py", line 19, in <module>
site.cd63130.tw1.ru [Fri Jan 17 19:35:04 2025] [error] [pid 2551433] src/server/wsgi_logger.c(147): [client 92.240.221.140:0]     from main import app as application
site.cd63130.tw1.ru [Fri Jan 17 19:35:04 2025] [error] [pid 2551433] src/server/wsgi_logger.c(147): [client 92.240.221.140:0]   File "/home/c/cd63130/site/public_html/main.py", line 86, in <module>
site.cd63130.tw1.ru [Fri Jan 17 19:35:04 2025] [error] [pid 2551433] src/server/wsgi_logger.c(147): [client 92.240.221.140:0]     user.set_password('admin')
site.cd63130.tw1.ru [Fri Jan 17 19:35:04 2025] [error] [pid 2551433] src/server/wsgi_logger.c(147): [client 92.240.221.140:0] AttributeError: 'User' object has no attribute 'set_password'
site.cd63130.tw1.ru [Fri Jan 17 19:36:01 2025] [error] [pid 2575356] src/server/mod_wsgi.c(3790): [client 87.250.224.230:0] mod_wsgi (pid=2575356): Failed to exec Python script file '/home/c/cd63130/site/public_html/passenger_wsgi.py'.
site.cd63130.tw1.ru [Fri Jan 17 19:36:01 2025] [error] [pid 2575356] src/server/wsgi_logger.c(628): [client 87.250.224.230:0] mod_wsgi (pid=2575356): Exception occurred processing WSGI script '/home/c/cd63130/site/public_html/passenger_wsgi.py'.
site.cd63130.tw1.ru [Fri Jan 17 19:36:01 2025] [error] [pid 2575356] src/server/wsgi_logger.c(147): [client 87.250.224.230:0] Traceback (most recent call last):
site.cd63130.tw1.ru [Fri Jan 17 19:36:01 2025] [error] [pid 2575356] src/server/wsgi_logger.c(147): [client 87.250.224.230:0]   File "/home/c/cd63130/site/public_html/passenger_wsgi.py", line 19, in <module>
site.cd63130.tw1.ru [Fri Jan 17 19:36:01 2025] [error] [pid 2575356] src/server/wsgi_logger.c(147): [client 87.250.224.230:0]     from main import app as application
site.cd63130.tw1.ru [Fri Jan 17 19:36:01 2025] [error] [pid 2575356] src/server/wsgi_logger.c(147): [client 87.250.224.230:0]   File "/home/c/cd63130/site/public_html/main.py", line 86, in <module>
site.cd63130.tw1.ru [Fri Jan 17 19:36:01 2025] [error] [pid 2575356] src/server/wsgi_logger.c(147): [client 87.250.224.230:0]     user.set_password('admin')
site.cd63130.tw1.ru [Fri Jan 17 19:36:01 2025] [error] [pid 2575356] src/server/wsgi_logger.c(147): [client 87.250.224.230:0] AttributeError: 'User' object has no attribute 'set_password'
site.cd63130.tw1.ru [Fri Jan 17 19:38:01 2025] [error] [pid 2641683] src/server/mod_wsgi.c(3790): [client 213.180.203.94:0] mod_wsgi (pid=2641683): Failed to exec Python script file '/home/c/cd63130/site/public_html/passenger_wsgi.py'.
site.cd63130.tw1.ru [Fri Jan 17 19:38:01 2025] [error] [pid 2641683] src/server/wsgi_logger.c(628): [client 213.180.203.94:0] mod_wsgi (pid=2641683): Exception occurred processing WSGI script '/home/c/cd63130/site/public_html/passenger_wsgi.py'.
site.cd63130.tw1.ru [Fri Jan 17 19:38:01 2025] [error] [pid 2641683] src/server/wsgi_logger.c(147): [client 213.180.203.94:0] Traceback (most recent call last):
site.cd63130.tw1.ru [Fri Jan 17 19:38:01 2025] [error] [pid 2641683] src/server/wsgi_logger.c(147): [client 213.180.203.94:0]   File "/home/c/cd63130/site/public_html/passenger_wsgi.py", line 19, in <module>
site.cd63130.tw1.ru [Fri Jan 17 19:38:01 2025] [error] [pid 2641683] src/server/wsgi_logger.c(147): [client 213.180.203.94:0]     from main import app as application
site.cd63130.tw1.ru [Fri Jan 17 19:38:01 2025] [error] [pid 2641683] src/server/wsgi_logger.c(147): [client 213.180.203.94:0]   File "/home/c/cd63130/site/public_html/main.py", line 86, in <module>
site.cd63130.tw1.ru [Fri Jan 17 19:38:01 2025] [error] [pid 2641683] src/server/wsgi_logger.c(147): [client 213.180.203.94:0]     user.set_password('admin')
site.cd63130.tw1.ru [Fri Jan 17 19:38:01 2025] [error] [pid 2641683] src/server/wsgi_logger.c(147): [client 213.180.203.94:0] AttributeError: 'User' object has no attribute 'set_password'
site.cd63130.tw1.ru [Fri Jan 17 19:40:01 2025] [error] [pid 2709053] src/server/mod_wsgi.c(3790): [client 213.180.203.17:0] mod_wsgi (pid=2709053): Failed to exec Python script file '/home/c/cd63130/site/public_html/passenger_wsgi.py'.
site.cd63130.tw1.ru [Fri Jan 17 19:40:01 2025] [error] [pid 2709053] src/server/wsgi_logger.c(628): [client 213.180.203.17:0] mod_wsgi (pid=2709053): Exception occurred processing WSGI script '/home/c/cd63130/site/public_html/passenger_wsgi.py'.
site.cd63130.tw1.ru [Fri Jan 17 19:40:01 2025] [error] [pid 2709053] src/server/wsgi_logger.c(147): [client 213.180.203.17:0] Traceback (most recent call last):
site.cd63130.tw1.ru [Fri Jan 17 19:40:01 2025] [error] [pid 2709053] src/server/wsgi_logger.c(147): [client 213.180.203.17:0]   File "/home/c/cd63130/site/public_html/passenger_wsgi.py", line 19, in <module>
site.cd63130.tw1.ru [Fri Jan 17 19:40:01 2025] [error] [pid 2709053] src/server/wsgi_logger.c(147): [client 213.180.203.17:0]     from main import app as application
site.cd63130.tw1.ru [Fri Jan 17 19:40:01 2025] [error] [pid 2709053] src/server/wsgi_logger.c(147): [client 213.180.203.17:0]   File "/home/c/cd63130/site/public_html/main.py", line 86, in <module>
site.cd63130.tw1.ru [Fri Jan 17 19:40:01 2025] [error] [pid 2709053] src/server/wsgi_logger.c(147): [client 213.180.203.17:0]     user.set_password('admin')
site.cd63130.tw1.ru [Fri Jan 17 19:40:01 2025] [error] [pid 2709053] src/server/wsgi_logger.c(147): [client 213.180.203.17:0] AttributeError: 'User' object has no attribute 'set_password'
site.cd63130.tw1.ru [Fri Jan 17 19:42:01 2025] [error] [pid 2771177] src/server/mod_wsgi.c(3790): [client 95.108.213.114:0] mod_wsgi (pid=2771177): Failed to exec Python script file '/home/c/cd63130/site/public_html/passenger_wsgi.py'.
site.cd63130.tw1.ru [Fri Jan 17 19:42:01 2025] [error] [pid 2771177] src/server/wsgi_logger.c(628): [client 95.108.213.114:0] mod_wsgi (pid=2771177): Exception occurred processing WSGI script '/home/c/cd63130/site/public_html/passenger_wsgi.py'.
site.cd63130.tw1.ru [Fri Jan 17 19:42:01 2025] [error] [pid 2771177] src/server/wsgi_logger.c(147): [client 95.108.213.114:0] Traceback (most recent call last):
site.cd63130.tw1.ru [Fri Jan 17 19:42:01 2025] [error] [pid 2771177] src/server/wsgi_logger.c(147): [client 95.108.213.114:0]   File "/home/c/cd63130/site/public_html/passenger_wsgi.py", line 19, in <module>
site.cd63130.tw1.ru [Fri Jan 17 19:42:01 2025] [error] [pid 2771177] src/server/wsgi_logger.c(147): [client 95.108.213.114:0]     from main import app as application
site.cd63130.tw1.ru [Fri Jan 17 19:42:01 2025] [error] [pid 2771177] src/server/wsgi_logger.c(147): [client 95.108.213.114:0]   File "/home/c/cd63130/site/public_html/main.py", line 86, in <module>
site.cd63130.tw1.ru [Fri Jan 17 19:42:01 2025] [error] [pid 2771177] src/server/wsgi_logger.c(147): [client 95.108.213.114:0]     user.set_password('admin')
site.cd63130.tw1.ru [Fri Jan 17 19:42:01 2025] [error] [pid 2771177] src/server/wsgi_logger.c(147): [client 95.108.213.114:0] AttributeError: 'User' object has no attribute 'set_password'
site.cd63130.tw1.ru [Fri Jan 17 19:44:01 2025] [error] [pid 2836939] src/server/mod_wsgi.c(3790): [client 5.255.231.35:0] mod_wsgi (pid=2836939): Failed to exec Python script file '/home/c/cd63130/site/public_html/passenger_wsgi.py'.
site.cd63130.tw1.ru [Fri Jan 17 19:44:01 2025] [error] [pid 2836939] src/server/wsgi_logger.c(628): [client 5.255.231.35:0] mod_wsgi (pid=2836939): Exception occurred processing WSGI script '/home/c/cd63130/site/public_html/passenger_wsgi.py'.
site.cd63130.tw1.ru [Fri Jan 17 19:44:01 2025] [error] [pid 2836939] src/server/wsgi_logger.c(147): [client 5.255.231.35:0] Traceback (most recent call last):
site.cd63130.tw1.ru [Fri Jan 17 19:44:01 2025] [error] [pid 2836939] src/server/wsgi_logger.c(147): [client 5.255.231.35:0]   File "/home/c/cd63130/site/public_html/passenger_wsgi.py", line 19, in <module>
site.cd63130.tw1.ru [Fri Jan 17 19:44:01 2025] [error] [pid 2836939] src/server/wsgi_logger.c(147): [client 5.255.231.35:0]     from main import app as application
site.cd63130.tw1.ru [Fri Jan 17 19:44:01 2025] [error] [pid 2836939] src/server/wsgi_logger.c(147): [client 5.255.231.35:0]   File "/home/c/cd63130/site/public_html/main.py", line 86, in <module>
site.cd63130.tw1.ru [Fri Jan 17 19:44:01 2025] [error] [pid 2836939] src/server/wsgi_logger.c(147): [client 5.255.231.35:0]     user.set_password('admin')
site.cd63130.tw1.ru [Fri Jan 17 19:44:01 2025] [error] [pid 2836939] src/server/wsgi_logger.c(147): [client 5.255.231.35:0] AttributeError: 'User' object has no attribute 'set_password'
site.cd63130.tw1.ru [Fri Jan 17 19:46:01 2025] [error] [pid 2902959] src/server/mod_wsgi.c(3790): [client 87.250.224.6:0] mod_wsgi (pid=2902959): Failed to exec Python script file '/home/c/cd63130/site/public_html/passenger_wsgi.py'.
site.cd63130.tw1.ru [Fri Jan 17 19:46:01 2025] [error] [pid 2902959] src/server/wsgi_logger.c(628): [client 87.250.224.6:0] mod_wsgi (pid=2902959): Exception occurred processing WSGI script '/home/c/cd63130/site/public_html/passenger_wsgi.py'.
site.cd63130.tw1.ru [Fri Jan 17 19:46:01 2025] [error] [pid 2902959] src/server/wsgi_logger.c(147): [client 87.250.224.6:0] Traceback (most recent call last):
site.cd63130.tw1.ru [Fri Jan 17 19:46:01 2025] [error] [pid 2902959] src/server/wsgi_logger.c(147): [client 87.250.224.6:0]   File "/home/c/cd63130/site/public_html/passenger_wsgi.py", line 19, in <module>
site.cd63130.tw1.ru [Fri Jan 17 19:46:01 2025] [error] [pid 2902959] src/server/wsgi_logger.c(147): [client 87.250.224.6:0]     from main import app as application
site.cd63130.tw1.ru [Fri Jan 17 19:46:01 2025] [error] [pid 2902959] src/server/wsgi_logger.c(147): [client 87.250.224.6:0]   File "/home/c/cd63130/site/public_html/main.py", line 86, in <module>
site.cd63130.tw1.ru [Fri Jan 17 19:46:01 2025] [error] [pid 2902959] src/server/wsgi_logger.c(147): [client 87.250.224.6:0]     user.set_password('admin')
site.cd63130.tw1.ru [Fri Jan 17 19:46:01 2025] [error] [pid 2902959] src/server/wsgi_logger.c(147): [client 87.250.224.6:0] AttributeError: 'User' object has no attribute 'set_password'
site.cd63130.tw1.ru [Fri Jan 17 19:46:02 2025] [error] [pid 2906032] src/server/mod_wsgi.c(3790): [client 95.108.213.192:0] mod_wsgi (pid=2906032): Failed to exec Python script file '/home/c/cd63130/site/public_html/passenger_wsgi.py'.
site.cd63130.tw1.ru [Fri Jan 17 19:46:02 2025] [error] [pid 2906032] src/server/wsgi_logger.c(628): [client 95.108.213.192:0] mod_wsgi (pid=2906032): Exception occurred processing WSGI script '/home/c/cd63130/site/public_html/passenger_wsgi.py'.
site.cd63130.tw1.ru [Fri Jan 17 19:46:02 2025] [error] [pid 2906032] src/server/wsgi_logger.c(147): [client 95.108.213.192:0] Traceback (most recent call last):
site.cd63130.tw1.ru [Fri Jan 17 19:46:02 2025] [error] [pid 2906032] src/server/wsgi_logger.c(147): [client 95.108.213.192:0]   File "/home/c/cd63130/site/public_html/passenger_wsgi.py", line 19, in <module>
site.cd63130.tw1.ru [Fri Jan 17 19:46:02 2025] [error] [pid 2906032] src/server/wsgi_logger.c(147): [client 95.108.213.192:0]     from main import app as application
site.cd63130.tw1.ru [Fri Jan 17 19:46:02 2025] [error] [pid 2906032] src/server/wsgi_logger.c(147): [client 95.108.213.192:0]   File "/home/c/cd63130/site/public_html/main.py", line 86, in <module>
site.cd63130.tw1.ru [Fri Jan 17 19:46:02 2025] [error] [pid 2906032] src/server/wsgi_logger.c(147): [client 95.108.213.192:0]     user.set_password('admin')
site.cd63130.tw1.ru [Fri Jan 17 19:46:02 2025] [error] [pid 2906032] src/server/wsgi_logger.c(147): [client 95.108.213.192:0] AttributeError: 'User' object has no attribute 'set_password'
site.cd63130.tw1.ru [Fri Jan 17 19:48:02 2025] [error] [pid 2980078] src/server/mod_wsgi.c(3790): [client 213.180.203.156:0] mod_wsgi (pid=2980078): Failed to exec Python script file '/home/c/cd63130/site/public_html/passenger_wsgi.py'.
site.cd63130.tw1.ru [Fri Jan 17 19:48:02 2025] [error] [pid 2980078] src/server/wsgi_logger.c(628): [client 213.180.203.156:0] mod_wsgi (pid=2980078): Exception occurred processing WSGI script '/home/c/cd63130/site/public_html/passenger_wsgi.py'.
site.cd63130.tw1.ru [Fri Jan 17 19:48:02 2025] [error] [pid 2980078] src/server/wsgi_logger.c(147): [client 213.180.203.156:0] Traceback (most recent call last):
site.cd63130.tw1.ru [Fri Jan 17 19:48:02 2025] [error] [pid 2980078] src/server/wsgi_logger.c(147): [client 213.180.203.156:0]   File "/home/c/cd63130/site/public_html/passenger_wsgi.py", line 19, in <module>
site.cd63130.tw1.ru [Fri Jan 17 19:48:02 2025] [error] [pid 2980078] src/server/wsgi_logger.c(147): [client 213.180.203.156:0]     from main import app as application
site.cd63130.tw1.ru [Fri Jan 17 19:48:02 2025] [error] [pid 2980078] src/server/wsgi_logger.c(147): [client 213.180.203.156:0]   File "/home/c/cd63130/site/public_html/main.py", line 86, in <module>
site.cd63130.tw1.ru [Fri Jan 17 19:48:02 2025] [error] [pid 2980078] src/server/wsgi_logger.c(147): [client 213.180.203.156:0]     user.set_password('admin')
site.cd63130.tw1.ru [Fri Jan 17 19:48:02 2025] [error] [pid 2980078] src/server/wsgi_logger.c(147): [client 213.180.203.156:0] AttributeError: 'User' object has no attribute 'set_password'
site.cd63130.tw1.ru [Fri Jan 17 19:52:02 2025] [error] [pid 3113084] src/server/mod_wsgi.c(3790): [client 87.250.224.80:0] mod_wsgi (pid=3113084): Failed to exec Python script file '/home/c/cd63130/site/public_html/passenger_wsgi.py'.
site.cd63130.tw1.ru [Fri Jan 17 19:52:02 2025] [error] [pid 3113084] src/server/wsgi_logger.c(628): [client 87.250.224.80:0] mod_wsgi (pid=3113084): Exception occurred processing WSGI script '/home/c/cd63130/site/public_html/passenger_wsgi.py'.
site.cd63130.tw1.ru [Fri Jan 17 19:52:02 2025] [error] [pid 3113084] src/server/wsgi_logger.c(147): [client 87.250.224.80:0] Traceback (most recent call last):
site.cd63130.tw1.ru [Fri Jan 17 19:52:02 2025] [error] [pid 3113084] src/server/wsgi_logger.c(147): [client 87.250.224.80:0]   File "/home/c/cd63130/site/public_html/passenger_wsgi.py", line 19, in <module>
site.cd63130.tw1.ru [Fri Jan 17 19:52:02 2025] [error] [pid 3113084] src/server/wsgi_logger.c(147): [client 87.250.224.80:0]     from main import app as application
site.cd63130.tw1.ru [Fri Jan 17 19:52:02 2025] [error] [pid 3113084] src/server/wsgi_logger.c(147): [client 87.250.224.80:0]   File "/home/c/cd63130/site/public_html/main.py", line 86, in <module>
site.cd63130.tw1.ru [Fri Jan 17 19:52:02 2025] [error] [pid 3113084] src/server/wsgi_logger.c(147): [client 87.250.224.80:0]     user.set_password('admin')
site.cd63130.tw1.ru [Fri Jan 17 19:52:02 2025] [error] [pid 3113084] src/server/wsgi_logger.c(147): [client 87.250.224.80:0] AttributeError: 'User' object has no attribute 'set_password'
site.cd63130.tw1.ru [Fri Jan 17 20:05:20 2025] [error] [pid 3576903] src/server/wsgi_logger.c(147): [client 92.240.221.140:0] ERROR:root:Database connection error: unable to open database file
site.cd63130.tw1.ru [Fri Jan 17 20:05:20 2025] [error] [pid 3576903] src/server/wsgi_logger.c(147): [client 92.240.221.140:0] \xd0\x9e\xd1\x88\xd0\xb8\xd0\xb1\xd0\xba\xd0\xb0 \xd0\xbf\xd1\x80\xd0\xb8 \xd0\xb7\xd0\xb0\xd0\xbf\xd0\xb8\xd1\x81\xd0\xb8 \xd0\xbf\xd0\xbe\xd1\x81\xd0\xb5\xd1\x89\xd0\xb5\xd0\xbd\xd0\xb8\xd1\x8f: unable to open database file
site.cd63130.tw1.ru [Fri Jan 17 20:05:20 2025] [error] [pid 3576903] src/server/wsgi_logger.c(147): [client 92.240.221.140:0] INFO:site:Page visit: /company - IP: gAAAAABnio3QziFHhbx5NZ2VERuf4W78EZGFfVj5XxVItRVxCX_bwyXiNRjbDShgrw38PzDpN5r6E1-DmDgwIY1nYo2sa7mGOg==
site.cd63130.tw1.ru [Fri Jan 17 20:05:24 2025] [error] [pid 3577919] src/server/wsgi_logger.c(147): [client 92.240.221.140:0] ERROR:root:Database connection error: unable to open database file
site.cd63130.tw1.ru [Fri Jan 17 20:05:24 2025] [error] [pid 3577919] src/server/wsgi_logger.c(147): [client 92.240.221.140:0] \xd0\x9e\xd1\x88\xd0\xb8\xd0\xb1\xd0\xba\xd0\xb0 \xd0\xbf\xd1\x80\xd0\xb8 \xd0\xb7\xd0\xb0\xd0\xbf\xd0\xb8\xd1\x81\xd0\xb8 \xd0\xbf\xd0\xbe\xd1\x81\xd0\xb5\xd1\x89\xd0\xb5\xd0\xbd\xd0\xb8\xd1\x8f: unable to open database file
site.cd63130.tw1.ru [Fri Jan 17 20:05:24 2025] [error] [pid 3577919] src/server/wsgi_logger.c(147): [client 92.240.221.140:0] INFO:site:Page visit: / - IP: gAAAAABnio3UuUAzAoizsGUiN4XRbWwBp1aeBg592ENf6FBgAlfgQfnCClIvduIdPCezlbicm-I97LCJCqoQSkSdKXfSL4pRHA==
site.cd63130.tw1.ru [Fri Jan 17 20:05:26 2025] [error] [pid 3578205] src/server/wsgi_logger.c(147): [client 92.240.221.140:0] ERROR:root:Database connection error: unable to open database file
site.cd63130.tw1.ru [Fri Jan 17 20:05:26 2025] [error] [pid 3578205] src/server/wsgi_logger.c(147): [client 92.240.221.140:0] \xd0\x9e\xd1\x88\xd0\xb8\xd0\xb1\xd0\xba\xd0\xb0 \xd0\xbf\xd1\x80\xd0\xb8 \xd0\xb7\xd0\xb0\xd0\xbf\xd0\xb8\xd1\x81\xd0\xb8 \xd0\xbf\xd0\xbe\xd1\x81\xd0\xb5\xd1\x89\xd0\xb5\xd0\xbd\xd0\xb8\xd1\x8f: unable to open database file
site.cd63130.tw1.ru [Fri Jan 17 20:05:26 2025] [error] [pid 3578205] src/server/wsgi_logger.c(147): [client 92.240.221.140:0] INFO:site:Page visit: /company - IP: gAAAAABnio3Wh0ybi3Xlb1Mu7pEVapap87EmXEA4Qlu8aLnzHSKYVB5NCft6ByH3DmH-xZScunR000eyxL0wbR4MLIY1q7srew==
site.cd63130.tw1.ru [Fri Jan 17 20:05:29 2025] [error] [pid 3579688] src/server/wsgi_logger.c(147): [client 92.240.221.140:0] ERROR:root:Database connection error: unable to open database file
site.cd63130.tw1.ru [Fri Jan 17 20:05:29 2025] [error] [pid 3579688] src/server/wsgi_logger.c(147): [client 92.240.221.140:0] \xd0\x9e\xd1\x88\xd0\xb8\xd0\xb1\xd0\xba\xd0\xb0 \xd0\xbf\xd1\x80\xd0\xb8 \xd0\xb7\xd0\xb0\xd0\xbf\xd0\xb8\xd1\x81\xd0\xb8 \xd0\xbf\xd0\xbe\xd1\x81\xd0\xb5\xd1\x89\xd0\xb5\xd0\xbd\xd0\xb8\xd1\x8f: unable to open database file
site.cd63130.tw1.ru [Fri Jan 17 20:05:29 2025] [error] [pid 3579688] src/server/wsgi_logger.c(147): [client 92.240.221.140:0] INFO:site:Page visit: /services - IP: gAAAAABnio3ZwFnyOQWYh34hVdawZGJhRhj16KSnOOxa1v8cUsqMtOwmpifTabcgLPDzPT3LA-woz06QI4KB_pJv62Co0cE5rA==
site.cd63130.tw1.ru [Fri Jan 17 20:05:31 2025] [error] [pid 3580017] src/server/wsgi_logger.c(147): [client 92.240.221.140:0] ERROR:root:Database connection error: unable to open database file
site.cd63130.tw1.ru [Fri Jan 17 20:05:31 2025] [error] [pid 3580017] src/server/wsgi_logger.c(147): [client 92.240.221.140:0] \xd0\x9e\xd1\x88\xd0\xb8\xd0\xb1\xd0\xba\xd0\xb0 \xd0\xbf\xd1\x80\xd0\xb8 \xd0\xb7\xd0\xb0\xd0\xbf\xd0\xb8\xd1\x81\xd0\xb8 \xd0\xbf\xd0\xbe\xd1\x81\xd0\xb5\xd1\x89\xd0\xb5\xd0\xbd\xd0\xb8\xd1\x8f: unable to open database file
site.cd63130.tw1.ru [Fri Jan 17 20:05:31 2025] [error] [pid 3580017] src/server/wsgi_logger.c(147): [client 92.240.221.140:0] INFO:site:Page visit: /contacts - IP: gAAAAABnio3bJTbCFLt9tb7L72L5AVRRPnOpuG1jv8iDvUZWCijXAhgkIex5W74SV4O2ELDhHZhZt0FQeif1GenuWzaduoFpDQ==
site.cd63130.tw1.ru [Fri Jan 17 20:05:34 2025] [error] [pid 3581036] src/server/wsgi_logger.c(147): [client 92.240.221.140:0] ERROR:root:Database connection error: unable to open database file
site.cd63130.tw1.ru [Fri Jan 17 20:05:34 2025] [error] [pid 3581036] src/server/wsgi_logger.c(147): [client 92.240.221.140:0] \xd0\x9e\xd1\x88\xd0\xb8\xd0\xb1\xd0\xba\xd0\xb0 \xd0\xbf\xd1\x80\xd0\xb8 \xd0\xb7\xd0\xb0\xd0\xbf\xd0\xb8\xd1\x81\xd0\xb8 \xd0\xbf\xd0\xbe\xd1\x81\xd0\xb5\xd1\x89\xd0\xb5\xd0\xbd\xd0\xb8\xd1\x8f: unable to open database file
site.cd63130.tw1.ru [Fri Jan 17 20:05:34 2025] [error] [pid 3581036] src/server/wsgi_logger.c(147): [client 92.240.221.140:0] INFO:site:Page visit: /repair-works - IP: gAAAAABnio3eRwmvkkyVXmaRzlq_MrJHQvfcTonYrVsZw37iqCIRfLbnGmNlVbiWE_bHusncG3UBM0q4UOJGTXfU2ANdvBV9Pg==
site.cd63130.tw1.ru [Fri Jan 17 20:05:36 2025] [error] [pid 3581292] src/server/wsgi_logger.c(147): [client 92.240.221.140:0] ERROR:root:Database connection error: unable to open database file
site.cd63130.tw1.ru [Fri Jan 17 20:05:36 2025] [error] [pid 3581292] src/server/wsgi_logger.c(147): [client 92.240.221.140:0] \xd0\x9e\xd1\x88\xd0\xb8\xd0\xb1\xd0\xba\xd0\xb0 \xd0\xbf\xd1\x80\xd0\xb8 \xd0\xb7\xd0\xb0\xd0\xbf\xd0\xb8\xd1\x81\xd0\xb8 \xd0\xbf\xd0\xbe\xd1\x81\xd0\xb5\xd1\x89\xd0\xb5\xd0\xbd\xd0\xb8\xd1\x8f: unable to open database file
site.cd63130.tw1.ru [Fri Jan 17 20:05:37 2025] [error] [pid 3581292] src/server/wsgi_logger.c(147): [client 92.240.221.140:0] INFO:site:Page visit: /serviced-objects - IP: gAAAAABnio3hJLvIOQxL82aoXO6sKpyanGcF0Mjx13QgoFtm7cw_CDRRiSwHcJzjnxtZ2gLik0xS67U7J8tY8OSPBQdx5kaC3g==
site.cd63130.tw1.ru [Fri Jan 17 20:05:38 2025] [error] [pid 3581503] src/server/wsgi_logger.c(147): [client 92.240.221.140:0] ERROR:root:Database connection error: unable to open database file
site.cd63130.tw1.ru [Fri Jan 17 20:05:38 2025] [error] [pid 3581503] src/server/wsgi_logger.c(147): [client 92.240.221.140:0] \xd0\x9e\xd1\x88\xd0\xb8\xd0\xb1\xd0\xba\xd0\xb0 \xd0\xbf\xd1\x80\xd0\xb8 \xd0\xb7\xd0\xb0\xd0\xbf\xd0\xb8\xd1\x81\xd0\xb8 \xd0\xbf\xd0\xbe\xd1\x81\xd0\xb5\xd1\x89\xd0\xb5\xd0\xbd\xd0\xb8\xd1\x8f: unable to open database file
site.cd63130.tw1.ru [Fri Jan 17 20:05:38 2025] [error] [pid 3581503] src/server/wsgi_logger.c(147): [client 92.240.221.140:0] INFO:site:Page visit: / - IP: gAAAAABnio3iOTGKbT1ey3ofm_qxfXEv7fxGVaorIMofeXcULGYhAGhEoFxG2c4LhaViWX70x3bVWavscZheah2es8eAQHttYA==
site.cd63130.tw1.ru [Fri Jan 17 20:05:47 2025] [error] [pid 3583810] src/server/wsgi_logger.c(147): [client 92.240.221.140:0] ERROR:root:Database connection error: unable to open database file
site.cd63130.tw1.ru [Fri Jan 17 20:05:47 2025] [error] [pid 3583810] src/server/wsgi_logger.c(147): [client 92.240.221.140:0] \xd0\x9e\xd1\x88\xd0\xb8\xd0\xb1\xd0\xba\xd0\xb0 \xd0\xbf\xd1\x80\xd0\xb8 \xd0\xb7\xd0\xb0\xd0\xbf\xd0\xb8\xd1\x81\xd0\xb8 \xd0\xbf\xd0\xbe\xd1\x81\xd0\xb5\xd1\x89\xd0\xb5\xd0\xbd\xd0\xb8\xd1\x8f: unable to open database file
site.cd63130.tw1.ru [Fri Jan 17 20:05:47 2025] [error] [pid 3583810] src/server/wsgi_logger.c(147): [client 92.240.221.140:0] INFO:site:Page visit: /admin/login - IP: gAAAAABnio3r3rRezpGxnIetdJRl4m79MnHz8RwXHofrj3dVnAw5wwoH9CnGOhqgjmnQdfKNP474BZQbJel91JerOxK-Ktmayw==
site.cd63130.tw1.ru [Fri Jan 17 20:05:53 2025] [error] [pid 3585131] src/server/wsgi_logger.c(147): [client 92.240.221.140:0] ERROR:root:Database connection error: unable to open database file
site.cd63130.tw1.ru [Fri Jan 17 20:05:53 2025] [error] [pid 3585131] src/server/wsgi_logger.c(147): [client 92.240.221.140:0] \xd0\x9e\xd1\x88\xd0\xb8\xd0\xb1\xd0\xba\xd0\xb0 \xd0\xbf\xd1\x80\xd0\xb8 \xd0\xb7\xd0\xb0\xd0\xbf\xd0\xb8\xd1\x81\xd0\xb8 \xd0\xbf\xd0\xbe\xd1\x81\xd0\xb5\xd1\x89\xd0\xb5\xd0\xbd\xd0\xb8\xd1\x8f: unable to open database file
site.cd63130.tw1.ru [Fri Jan 17 20:05:53 2025] [error] [pid 3585131] src/server/wsgi_logger.c(147): [client 92.240.221.140:0] INFO:site:Page visit: /admin/login - IP: gAAAAABnio3xYLrwYw3JPMS0LowZz9qWErgq1z6LIqVvBvBTHxaAmZnX_Fo7nLWnMQ2qSxCBVrySchj4kBUbIWbQorXYlUoccQ==
site.cd63130.tw1.ru [Fri Jan 17 20:05:53 2025] [error] [pid 3585131] src/server/wsgi_logger.c(147): [client 92.240.221.140:0] ERROR:root:Login error: (sqlite3.OperationalError) no such column: users.last_login
site.cd63130.tw1.ru [Fri Jan 17 20:05:53 2025] [error] [pid 3585131] src/server/wsgi_logger.c(147): [client 92.240.221.140:0] [SQL: SELECT users.id AS users_id, users.username AS users_username, users.password AS users_password, users.created_at AS users_created_at, users.last_login AS users_last_login
site.cd63130.tw1.ru [Fri Jan 17 20:05:53 2025] [error] [pid 3585131] src/server/wsgi_logger.c(147): [client 92.240.221.140:0] FROM users
site.cd63130.tw1.ru [Fri Jan 17 20:05:53 2025] [error] [pid 3585131] src/server/wsgi_logger.c(147): [client 92.240.221.140:0] WHERE users.username = ?
site.cd63130.tw1.ru [Fri Jan 17 20:05:53 2025] [error] [pid 3585131] src/server/wsgi_logger.c(147): [client 92.240.221.140:0]  LIMIT ? OFFSET ?]
site.cd63130.tw1.ru [Fri Jan 17 20:05:53 2025] [error] [pid 3585131] src/server/wsgi_logger.c(147): [client 92.240.221.140:0] [parameters: ('admin', 1, 0)]
site.cd63130.tw1.ru [Fri Jan 17 20:05:53 2025] [error] [pid 3585131] src/server/wsgi_logger.c(147): [client 92.240.221.140:0] (Background on this error at: https://sqlalche.me/e/20/e3q8)
site.cd63130.tw1.ru [Fri Jan 17 20:11:36 2025] [error] [pid 3781334] src/server/wsgi_logger.c(147): [client 92.240.221.140:0] ERROR:root:Database connection error: unable to open database file
site.cd63130.tw1.ru [Fri Jan 17 20:11:36 2025] [error] [pid 3781334] src/server/wsgi_logger.c(147): [client 92.240.221.140:0] \xd0\x9e\xd1\x88\xd0\xb8\xd0\xb1\xd0\xba\xd0\xb0 \xd0\xbf\xd1\x80\xd0\xb8 \xd0\xb7\xd0\xb0\xd0\xbf\xd0\xb8\xd1\x81\xd0\xb8 \xd0\xbf\xd0\xbe\xd1\x81\xd0\xb5\xd1\x89\xd0\xb5\xd0\xbd\xd0\xb8\xd1\x8f: unable to open database file
site.cd63130.tw1.ru [Fri Jan 17 20:11:36 2025] [error] [pid 3781334] src/server/wsgi_logger.c(147): [client 92.240.221.140:0] INFO:site:Page visit: /admin/login - IP: gAAAAABnio9IT1xkAmsQWhLD0F9M12Q8VkYzlmIe6IFmVAbzUcqywYCc35E0hJb6LBR9YVBKPZGmF_nOYFkA-k64ce_SwZlHwA==
site.cd63130.tw1.ru [Fri Jan 17 20:11:36 2025] [error] [pid 3781334] src/server/wsgi_logger.c(147): [client 92.240.221.140:0] ERROR:root:Login error: (sqlite3.OperationalError) no such column: users.last_login
site.cd63130.tw1.ru [Fri Jan 17 20:11:36 2025] [error] [pid 3781334] src/server/wsgi_logger.c(147): [client 92.240.221.140:0] [SQL: SELECT users.id AS users_id, users.username AS users_username, users.password AS users_password, users.created_at AS users_created_at, users.last_login AS users_last_login
site.cd63130.tw1.ru [Fri Jan 17 20:11:36 2025] [error] [pid 3781334] src/server/wsgi_logger.c(147): [client 92.240.221.140:0] FROM users
site.cd63130.tw1.ru [Fri Jan 17 20:11:36 2025] [error] [pid 3781334] src/server/wsgi_logger.c(147): [client 92.240.221.140:0] WHERE users.username = ?
site.cd63130.tw1.ru [Fri Jan 17 20:11:36 2025] [error] [pid 3781334] src/server/wsgi_logger.c(147): [client 92.240.221.140:0]  LIMIT ? OFFSET ?]
site.cd63130.tw1.ru [Fri Jan 17 20:11:36 2025] [error] [pid 3781334] src/server/wsgi_logger.c(147): [client 92.240.221.140:0] [parameters: ('admin', 1, 0)]
site.cd63130.tw1.ru [Fri Jan 17 20:11:36 2025] [error] [pid 3781334] src/server/wsgi_logger.c(147): [client 92.240.221.140:0] (Background on this error at: https://sqlalche.me/e/20/e3q8)
site.cd63130.tw1.ru [Fri Jan 17 20:11:45 2025] [error] [pid 3784002] src/server/wsgi_logger.c(147): [client 92.240.221.140:0] ERROR:root:Database connection error: unable to open database file
site.cd63130.tw1.ru [Fri Jan 17 20:11:45 2025] [error] [pid 3784002] src/server/wsgi_logger.c(147): [client 92.240.221.140:0] \xd0\x9e\xd1\x88\xd0\xb8\xd0\xb1\xd0\xba\xd0\xb0 \xd0\xbf\xd1\x80\xd0\xb8 \xd0\xb7\xd0\xb0\xd0\xbf\xd0\xb8\xd1\x81\xd0\xb8 \xd0\xbf\xd0\xbe\xd1\x81\xd0\xb5\xd1\x89\xd0\xb5\xd0\xbd\xd0\xb8\xd1\x8f: unable to open database file
site.cd63130.tw1.ru [Fri Jan 17 20:11:45 2025] [error] [pid 3784002] src/server/wsgi_logger.c(147): [client 92.240.221.140:0] INFO:site:Page visit: /admin/login - IP: gAAAAABnio9RrkxthuiAILpzO1LbTRoKiZB00fF8Zxbvs0f4S_1OHLjr6Tyr6LQsuD4iuf8Q99441l1o_4z8i554zGINBJ-erA==
site.cd63130.tw1.ru [Fri Jan 17 20:11:45 2025] [error] [pid 3784002] src/server/wsgi_logger.c(147): [client 92.240.221.140:0] ERROR:root:Login error: (sqlite3.OperationalError) no such column: users.last_login
site.cd63130.tw1.ru [Fri Jan 17 20:11:45 2025] [error] [pid 3784002] src/server/wsgi_logger.c(147): [client 92.240.221.140:0] [SQL: SELECT users.id AS users_id, users.username AS users_username, users.password AS users_password, users.created_at AS users_created_at, users.last_login AS users_last_login
site.cd63130.tw1.ru [Fri Jan 17 20:11:45 2025] [error] [pid 3784002] src/server/wsgi_logger.c(147): [client 92.240.221.140:0] FROM users
site.cd63130.tw1.ru [Fri Jan 17 20:11:45 2025] [error] [pid 3784002] src/server/wsgi_logger.c(147): [client 92.240.221.140:0] WHERE users.username = ?
site.cd63130.tw1.ru [Fri Jan 17 20:11:45 2025] [error] [pid 3784002] src/server/wsgi_logger.c(147): [client 92.240.221.140:0]  LIMIT ? OFFSET ?]
site.cd63130.tw1.ru [Fri Jan 17 20:11:45 2025] [error] [pid 3784002] src/server/wsgi_logger.c(147): [client 92.240.221.140:0] [parameters: ('admin', 1, 0)]
site.cd63130.tw1.ru [Fri Jan 17 20:11:45 2025] [error] [pid 3784002] src/server/wsgi_logger.c(147): [client 92.240.221.140:0] (Background on this error at: https://sqlalche.me/e/20/e3q8)
site.cd63130.tw1.ru [Fri Jan 17 20:11:52 2025] [error] [pid 3785948] src/server/wsgi_logger.c(147): [client 92.240.221.140:0] ERROR:root:Database connection error: unable to open database file
site.cd63130.tw1.ru [Fri Jan 17 20:11:52 2025] [error] [pid 3785948] src/server/wsgi_logger.c(147): [client 92.240.221.140:0] \xd0\x9e\xd1\x88\xd0\xb8\xd0\xb1\xd0\xba\xd0\xb0 \xd0\xbf\xd1\x80\xd0\xb8 \xd0\xb7\xd0\xb0\xd0\xbf\xd0\xb8\xd1\x81\xd0\xb8 \xd0\xbf\xd0\xbe\xd1\x81\xd0\xb5\xd1\x89\xd0\xb5\xd0\xbd\xd0\xb8\xd1\x8f: unable to open database file
site.cd63130.tw1.ru [Fri Jan 17 20:11:52 2025] [error] [pid 3785948] src/server/wsgi_logger.c(147): [client 92.240.221.140:0] INFO:site:Page visit: /admin/login - IP: gAAAAABnio9YUNoe7pdSnA_XedxJ4OZ8TQgtDm9DXNh81YjYoPewO9PKVsH_z4XKL3lGq82mKXIh2pDVgkMWwcPXT97CQ0sz7w==
site.cd63130.tw1.ru [Fri Jan 17 20:11:52 2025] [error] [pid 3785948] src/server/wsgi_logger.c(147): [client 92.240.221.140:0] ERROR:root:Login error: (sqlite3.OperationalError) no such column: users.last_login
site.cd63130.tw1.ru [Fri Jan 17 20:11:52 2025] [error] [pid 3785948] src/server/wsgi_logger.c(147): [client 92.240.221.140:0] [SQL: SELECT users.id AS users_id, users.username AS users_username, users.password AS users_password, users.created_at AS users_created_at, users.last_login AS users_last_login
site.cd63130.tw1.ru [Fri Jan 17 20:11:52 2025] [error] [pid 3785948] src/server/wsgi_logger.c(147): [client 92.240.221.140:0] FROM users
site.cd63130.tw1.ru [Fri Jan 17 20:11:52 2025] [error] [pid 3785948] src/server/wsgi_logger.c(147): [client 92.240.221.140:0] WHERE users.username = ?
site.cd63130.tw1.ru [Fri Jan 17 20:11:52 2025] [error] [pid 3785948] src/server/wsgi_logger.c(147): [client 92.240.221.140:0]  LIMIT ? OFFSET ?]
site.cd63130.tw1.ru [Fri Jan 17 20:11:52 2025] [error] [pid 3785948] src/server/wsgi_logger.c(147): [client 92.240.221.140:0] [parameters: ('admin', 1, 0)]
site.cd63130.tw1.ru [Fri Jan 17 20:11:52 2025] [error] [pid 3785948] src/server/wsgi_logger.c(147): [client 92.240.221.140:0] (Background on this error at: https://sqlalche.me/e/20/e3q8)
site.cd63130.tw1.ru [Fri Jan 17 20:20:24 2025] [error] [pid 4104159] src/server/wsgi_logger.c(147): [client 176.53.221.147:0] ERROR:root:Database connection error: unable to open database file
site.cd63130.tw1.ru [Fri Jan 17 20:20:24 2025] [error] [pid 4104159] src/server/wsgi_logger.c(147): [client 176.53.221.147:0] \xd0\x9e\xd1\x88\xd0\xb8\xd0\xb1\xd0\xba\xd0\xb0 \xd0\xbf\xd1\x80\xd0\xb8 \xd0\xb7\xd0\xb0\xd0\xbf\xd0\xb8\xd1\x81\xd0\xb8 \xd0\xbf\xd0\xbe\xd1\x81\xd0\xb5\xd1\x89\xd0\xb5\xd0\xbd\xd0\xb8\xd1\x8f: unable to open database file
site.cd63130.tw1.ru [Fri Jan 17 20:20:24 2025] [error] [pid 4104159] src/server/wsgi_logger.c(147): [client 176.53.221.147:0] INFO:site:Page visit: / - IP: gAAAAABnipFYy3kkVpRptdRJUfzNp2zrglLavJ-gFk3I5_tzyJ3rVwYTeCT6nyE2zAF3jJnkcoxkAi7A1BEKClxOvK7B3OayfQ==
site.cd63130.tw1.ru [Fri Jan 17 20:20:25 2025] [error] [pid 4104513] src/server/wsgi_logger.c(147): [client 176.53.221.147:0] ERROR:root:Database connection error: unable to open database file
site.cd63130.tw1.ru [Fri Jan 17 20:20:25 2025] [error] [pid 4104513] src/server/wsgi_logger.c(147): [client 176.53.221.147:0] \xd0\x9e\xd1\x88\xd0\xb8\xd0\xb1\xd0\xba\xd0\xb0 \xd0\xbf\xd1\x80\xd0\xb8 \xd0\xb7\xd0\xb0\xd0\xbf\xd0\xb8\xd1\x81\xd0\xb8 \xd0\xbf\xd0\xbe\xd1\x81\xd0\xb5\xd1\x89\xd0\xb5\xd0\xbd\xd0\xb8\xd1\x8f: unable to open database file
site.cd63130.tw1.ru [Fri Jan 17 20:20:25 2025] [error] [pid 4104513] src/server/wsgi_logger.c(147): [client 176.53.221.147:0] INFO:site:Page visit: /favicon.ico - IP: gAAAAABnipFZ3tAghhpll0xMWsLUCj43f6N4Bih8Eb1aZo2K3Ghw4Qtj9SY-aYGZOzDwuZit5O-3j5hTyQ5pFLUepUXldeLaIg==
site.cd63130.tw1.ru [Fri Jan 17 20:20:38 2025] [error] [pid 4110581] src/server/wsgi_logger.c(147): [client 89.104.101.183:0] ERROR:root:Database connection error: unable to open database file
site.cd63130.tw1.ru [Fri Jan 17 20:20:38 2025] [error] [pid 4110581] src/server/wsgi_logger.c(147): [client 89.104.101.183:0] \xd0\x9e\xd1\x88\xd0\xb8\xd0\xb1\xd0\xba\xd0\xb0 \xd0\xbf\xd1\x80\xd0\xb8 \xd0\xb7\xd0\xb0\xd0\xbf\xd0\xb8\xd1\x81\xd0\xb8 \xd0\xbf\xd0\xbe\xd1\x81\xd0\xb5\xd1\x89\xd0\xb5\xd0\xbd\xd0\xb8\xd1\x8f: unable to open database file
site.cd63130.tw1.ru [Fri Jan 17 20:20:38 2025] [error] [pid 4110581] src/server/wsgi_logger.c(147): [client 89.104.101.183:0] INFO:site:Page visit: / - IP: gAAAAABnipFmuO4CPuiP-IPxi57y8t8qnCL7ND9nl00EP_O6V4i0nU22IzBKEvDAdJtbufObXnrjL2hKWadpLUTdPluiOJ-EUA==
site.cd63130.tw1.ru [Fri Jan 17 20:20:39 2025] [error] [pid 4110801] src/server/wsgi_logger.c(147): [client 45.90.61.76:0] ERROR:root:Database connection error: unable to open database file
site.cd63130.tw1.ru [Fri Jan 17 20:20:39 2025] [error] [pid 4110801] src/server/wsgi_logger.c(147): [client 45.90.61.76:0] \xd0\x9e\xd1\x88\xd0\xb8\xd0\xb1\xd0\xba\xd0\xb0 \xd0\xbf\xd1\x80\xd0\xb8 \xd0\xb7\xd0\xb0\xd0\xbf\xd0\xb8\xd1\x81\xd0\xb8 \xd0\xbf\xd0\xbe\xd1\x81\xd0\xb5\xd1\x89\xd0\xb5\xd0\xbd\xd0\xb8\xd1\x8f: unable to open database file
site.cd63130.tw1.ru [Fri Jan 17 20:20:40 2025] [error] [pid 4110801] src/server/wsgi_logger.c(147): [client 45.90.61.76:0] INFO:site:Page visit: /favicon.ico - IP: gAAAAABnipFogR-_LERDoB3R1v4F3EFa1guqe4bj1Olz4J5eNWv1Da6sy5tUU6yLVgRXyvGn8-_p7s38XhQvqEx5x7TTTKPJmw==
